[Tue Apr 22 11:29:20.637608 2014] [:error] [pid 13534:tid 140253146896128] [client 127.0.0.1:59404] mod_wsgi (pid=13534): Target WSGI script '/var/www/getip.com/ip/wsgi.py' cannot be loaded as Python module.
[Tue Apr 22 11:29:20.637708 2014] [:error] [pid 13534:tid 140253146896128] [client 127.0.0.1:59404] mod_wsgi (pid=13534): Exception occurred processing WSGI script '/var/www/getip.com/ip/wsgi.py'.
[Tue Apr 22 11:29:20.637735 2014] [:error] [pid 13534:tid 140253146896128] [client 127.0.0.1:59404] Traceback (most recent call last):
[Tue Apr 22 11:29:20.638853 2014] [:error] [pid 13534:tid 140253146896128] [client 127.0.0.1:59404]   File "/var/www/getip.com/ip/wsgi.py", line 13, in <module>
[Tue Apr 22 11:29:20.640829 2014] [:error] [pid 13534:tid 140253146896128] [client 127.0.0.1:59404]     from django.core.wsgi import get_wsgi_application
[Tue Apr 22 11:29:20.640857 2014] [:error] [pid 13534:tid 140253146896128] [client 127.0.0.1:59404] ImportError: No module named django.core.wsgi
[Tue Apr 22 11:31:51.761718 2014] [:error] [pid 13533:tid 140253291730688] [client 127.0.0.1:59413] mod_wsgi (pid=13533): Target WSGI script '/var/www/getip.com/ip/wsgi.py' cannot be loaded as Python module.
[Tue Apr 22 11:31:51.761803 2014] [:error] [pid 13533:tid 140253291730688] [client 127.0.0.1:59413] mod_wsgi (pid=13533): Exception occurred processing WSGI script '/var/www/getip.com/ip/wsgi.py'.
[Tue Apr 22 11:31:51.761827 2014] [:error] [pid 13533:tid 140253291730688] [client 127.0.0.1:59413] Traceback (most recent call last):
[Tue Apr 22 11:31:51.761851 2014] [:error] [pid 13533:tid 140253291730688] [client 127.0.0.1:59413]   File "/var/www/getip.com/ip/wsgi.py", line 13, in <module>
[Tue Apr 22 11:31:51.761900 2014] [:error] [pid 13533:tid 140253291730688] [client 127.0.0.1:59413]     from django.core.wsgi import get_wsgi_application
[Tue Apr 22 11:31:51.761916 2014] [:error] [pid 13533:tid 140253291730688] [client 127.0.0.1:59413] ImportError: No module named django.core.wsgi
[Tue Apr 22 11:31:53.147678 2014] [:error] [pid 13534:tid 140253155288832] [client 127.0.0.1:59414] mod_wsgi (pid=13534): Target WSGI script '/var/www/getip.com/ip/wsgi.py' cannot be loaded as Python module.
[Tue Apr 22 11:31:53.147737 2014] [:error] [pid 13534:tid 140253155288832] [client 127.0.0.1:59414] mod_wsgi (pid=13534): Exception occurred processing WSGI script '/var/www/getip.com/ip/wsgi.py'.
[Tue Apr 22 11:31:53.147793 2014] [:error] [pid 13534:tid 140253155288832] [client 127.0.0.1:59414] Traceback (most recent call last):
[Tue Apr 22 11:31:53.147837 2014] [:error] [pid 13534:tid 140253155288832] [client 127.0.0.1:59414]   File "/var/www/getip.com/ip/wsgi.py", line 13, in <module>
[Tue Apr 22 11:31:53.147900 2014] [:error] [pid 13534:tid 140253155288832] [client 127.0.0.1:59414]     from django.core.wsgi import get_wsgi_application
[Tue Apr 22 11:31:53.147942 2014] [:error] [pid 13534:tid 140253155288832] [client 127.0.0.1:59414] ImportError: No module named django.core.wsgi
[Tue Apr 22 11:31:54.440252 2014] [:error] [pid 13534:tid 140253163681536] [client 127.0.0.1:59415] mod_wsgi (pid=13534): Target WSGI script '/var/www/getip.com/ip/wsgi.py' cannot be loaded as Python module.
[Tue Apr 22 11:31:54.440300 2014] [:error] [pid 13534:tid 140253163681536] [client 127.0.0.1:59415] mod_wsgi (pid=13534): Exception occurred processing WSGI script '/var/www/getip.com/ip/wsgi.py'.
[Tue Apr 22 11:31:54.440331 2014] [:error] [pid 13534:tid 140253163681536] [client 127.0.0.1:59415] Traceback (most recent call last):
[Tue Apr 22 11:31:54.440361 2014] [:error] [pid 13534:tid 140253163681536] [client 127.0.0.1:59415]   File "/var/www/getip.com/ip/wsgi.py", line 13, in <module>
[Tue Apr 22 11:31:54.440401 2014] [:error] [pid 13534:tid 140253163681536] [client 127.0.0.1:59415]     from django.core.wsgi import get_wsgi_application
[Tue Apr 22 11:31:54.440427 2014] [:error] [pid 13534:tid 140253163681536] [client 127.0.0.1:59415] ImportError: No module named django.core.wsgi
[Tue Apr 22 11:31:54.772685 2014] [:error] [pid 13534:tid 140253241358080] [client 127.0.0.1:59416] mod_wsgi (pid=13534): Target WSGI script '/var/www/getip.com/ip/wsgi.py' cannot be loaded as Python module.
[Tue Apr 22 11:31:54.772757 2014] [:error] [pid 13534:tid 140253241358080] [client 127.0.0.1:59416] mod_wsgi (pid=13534): Exception occurred processing WSGI script '/var/www/getip.com/ip/wsgi.py'.
[Tue Apr 22 11:31:54.772798 2014] [:error] [pid 13534:tid 140253241358080] [client 127.0.0.1:59416] Traceback (most recent call last):
[Tue Apr 22 11:31:54.772837 2014] [:error] [pid 13534:tid 140253241358080] [client 127.0.0.1:59416]   File "/var/www/getip.com/ip/wsgi.py", line 13, in <module>
[Tue Apr 22 11:31:54.772887 2014] [:error] [pid 13534:tid 140253241358080] [client 127.0.0.1:59416]     from django.core.wsgi import get_wsgi_application
[Tue Apr 22 11:31:54.772922 2014] [:error] [pid 13534:tid 140253241358080] [client 127.0.0.1:59416] ImportError: No module named django.core.wsgi
[Tue Apr 22 11:31:57.236388 2014] [:error] [pid 13533:tid 140253274945280] [client 127.0.0.1:59417] mod_wsgi (pid=13533): Target WSGI script '/var/www/getip.com/ip/wsgi.py' cannot be loaded as Python module.
[Tue Apr 22 11:31:57.236423 2014] [:error] [pid 13533:tid 140253274945280] [client 127.0.0.1:59417] mod_wsgi (pid=13533): Exception occurred processing WSGI script '/var/www/getip.com/ip/wsgi.py'.
[Tue Apr 22 11:31:57.236443 2014] [:error] [pid 13533:tid 140253274945280] [client 127.0.0.1:59417] Traceback (most recent call last):
[Tue Apr 22 11:31:57.236463 2014] [:error] [pid 13533:tid 140253274945280] [client 127.0.0.1:59417]   File "/var/www/getip.com/ip/wsgi.py", line 13, in <module>
[Tue Apr 22 11:31:57.236488 2014] [:error] [pid 13533:tid 140253274945280] [client 127.0.0.1:59417]     from django.core.wsgi import get_wsgi_application
[Tue Apr 22 11:31:57.236505 2014] [:error] [pid 13533:tid 140253274945280] [client 127.0.0.1:59417] ImportError: No module named django.core.wsgi
[Tue Apr 22 11:31:57.936301 2014] [:error] [pid 13533:tid 140253266552576] [client 127.0.0.1:59418] mod_wsgi (pid=13533): Target WSGI script '/var/www/getip.com/ip/wsgi.py' cannot be loaded as Python module.
[Tue Apr 22 11:31:57.936330 2014] [:error] [pid 13533:tid 140253266552576] [client 127.0.0.1:59418] mod_wsgi (pid=13533): Exception occurred processing WSGI script '/var/www/getip.com/ip/wsgi.py'.
[Tue Apr 22 11:31:57.936351 2014] [:error] [pid 13533:tid 140253266552576] [client 127.0.0.1:59418] Traceback (most recent call last):
[Tue Apr 22 11:31:57.936372 2014] [:error] [pid 13533:tid 140253266552576] [client 127.0.0.1:59418]   File "/var/www/getip.com/ip/wsgi.py", line 13, in <module>
[Tue Apr 22 11:31:57.936398 2014] [:error] [pid 13533:tid 140253266552576] [client 127.0.0.1:59418]     from django.core.wsgi import get_wsgi_application
[Tue Apr 22 11:31:57.936416 2014] [:error] [pid 13533:tid 140253266552576] [client 127.0.0.1:59418] ImportError: No module named django.core.wsgi
[Tue Apr 22 11:32:00.643539 2014] [:error] [pid 13533:tid 140253138503424] [client 127.0.0.1:59419] mod_wsgi (pid=13533): Target WSGI script '/var/www/getip.com/ip/wsgi.py' cannot be loaded as Python module.
[Tue Apr 22 11:32:00.643578 2014] [:error] [pid 13533:tid 140253138503424] [client 127.0.0.1:59419] mod_wsgi (pid=13533): Exception occurred processing WSGI script '/var/www/getip.com/ip/wsgi.py'.
[Tue Apr 22 11:32:00.643601 2014] [:error] [pid 13533:tid 140253138503424] [client 127.0.0.1:59419] Traceback (most recent call last):
[Tue Apr 22 11:32:00.643622 2014] [:error] [pid 13533:tid 140253138503424] [client 127.0.0.1:59419]   File "/var/www/getip.com/ip/wsgi.py", line 13, in <module>
[Tue Apr 22 11:32:00.643650 2014] [:error] [pid 13533:tid 140253138503424] [client 127.0.0.1:59419]     from django.core.wsgi import get_wsgi_application
[Tue Apr 22 11:32:00.643668 2014] [:error] [pid 13533:tid 140253138503424] [client 127.0.0.1:59419] ImportError: No module named django.core.wsgi
[Tue Apr 22 11:36:20.970230 2014] [:error] [pid 14213:tid 140589932427008] [client 127.0.0.1:59459] mod_wsgi (pid=14213): Target WSGI script '/var/www/getip.com/ip/wsgi.py' cannot be loaded as Python module.
[Tue Apr 22 11:36:20.970309 2014] [:error] [pid 14213:tid 140589932427008] [client 127.0.0.1:59459] mod_wsgi (pid=14213): Exception occurred processing WSGI script '/var/www/getip.com/ip/wsgi.py'.
[Tue Apr 22 11:36:20.970325 2014] [:error] [pid 14213:tid 140589932427008] [client 127.0.0.1:59459] Traceback (most recent call last):
[Tue Apr 22 11:36:20.970340 2014] [:error] [pid 14213:tid 140589932427008] [client 127.0.0.1:59459]   File "/var/www/getip.com/ip/wsgi.py", line 13, in <module>
[Tue Apr 22 11:36:20.970384 2014] [:error] [pid 14213:tid 140589932427008] [client 127.0.0.1:59459]     from django.core.wsgi import get_wsgi_application
[Tue Apr 22 11:36:20.970398 2014] [:error] [pid 14213:tid 140589932427008] [client 127.0.0.1:59459] ImportError: No module named django.core.wsgi
[Tue Apr 22 11:36:21.814312 2014] [:error] [pid 14215:tid 140589840459520] [client 127.0.0.1:59460] mod_wsgi (pid=14215): Target WSGI script '/var/www/getip.com/ip/wsgi.py' cannot be loaded as Python module.
[Tue Apr 22 11:36:21.814377 2014] [:error] [pid 14215:tid 140589840459520] [client 127.0.0.1:59460] mod_wsgi (pid=14215): Exception occurred processing WSGI script '/var/www/getip.com/ip/wsgi.py'.
[Tue Apr 22 11:36:21.814392 2014] [:error] [pid 14215:tid 140589840459520] [client 127.0.0.1:59460] Traceback (most recent call last):
[Tue Apr 22 11:36:21.814406 2014] [:error] [pid 14215:tid 140589840459520] [client 127.0.0.1:59460]   File "/var/www/getip.com/ip/wsgi.py", line 13, in <module>
[Tue Apr 22 11:36:21.814444 2014] [:error] [pid 14215:tid 140589840459520] [client 127.0.0.1:59460]     from django.core.wsgi import get_wsgi_application
[Tue Apr 22 11:36:21.814458 2014] [:error] [pid 14215:tid 140589840459520] [client 127.0.0.1:59460] ImportError: No module named django.core.wsgi
[Tue Apr 22 11:36:22.192522 2014] [:error] [pid 14213:tid 140589815281408] [client 127.0.0.1:59461] mod_wsgi (pid=14213): Target WSGI script '/var/www/getip.com/ip/wsgi.py' cannot be loaded as Python module.
[Tue Apr 22 11:36:22.192550 2014] [:error] [pid 14213:tid 140589815281408] [client 127.0.0.1:59461] mod_wsgi (pid=14213): Exception occurred processing WSGI script '/var/www/getip.com/ip/wsgi.py'.
[Tue Apr 22 11:36:22.192571 2014] [:error] [pid 14213:tid 140589815281408] [client 127.0.0.1:59461] Traceback (most recent call last):
[Tue Apr 22 11:36:22.192592 2014] [:error] [pid 14213:tid 140589815281408] [client 127.0.0.1:59461]   File "/var/www/getip.com/ip/wsgi.py", line 13, in <module>
[Tue Apr 22 11:36:22.192618 2014] [:error] [pid 14213:tid 140589815281408] [client 127.0.0.1:59461]     from django.core.wsgi import get_wsgi_application
[Tue Apr 22 11:36:22.192635 2014] [:error] [pid 14213:tid 140589815281408] [client 127.0.0.1:59461] ImportError: No module named django.core.wsgi
[Tue Apr 22 11:36:22.420042 2014] [:error] [pid 14213:tid 140589848852224] [client 127.0.0.1:59462] mod_wsgi (pid=14213): Target WSGI script '/var/www/getip.com/ip/wsgi.py' cannot be loaded as Python module.
[Tue Apr 22 11:36:22.420069 2014] [:error] [pid 14213:tid 140589848852224] [client 127.0.0.1:59462] mod_wsgi (pid=14213): Exception occurred processing WSGI script '/var/www/getip.com/ip/wsgi.py'.
[Tue Apr 22 11:36:22.420092 2014] [:error] [pid 14213:tid 140589848852224] [client 127.0.0.1:59462] Traceback (most recent call last):
[Tue Apr 22 11:36:22.420112 2014] [:error] [pid 14213:tid 140589848852224] [client 127.0.0.1:59462]   File "/var/www/getip.com/ip/wsgi.py", line 13, in <module>
[Tue Apr 22 11:36:22.420139 2014] [:error] [pid 14213:tid 140589848852224] [client 127.0.0.1:59462]     from django.core.wsgi import get_wsgi_application
[Tue Apr 22 11:36:22.420157 2014] [:error] [pid 14213:tid 140589848852224] [client 127.0.0.1:59462] ImportError: No module named django.core.wsgi
[Tue Apr 22 11:44:21.340118 2014] [:error] [pid 14399:tid 139922307860224] [client 127.0.0.1:59657] mod_wsgi (pid=14399): Target WSGI script '/var/www/getip.com/ip/wsgi.py' cannot be loaded as Python module.
[Tue Apr 22 11:44:21.340184 2014] [:error] [pid 14399:tid 139922307860224] [client 127.0.0.1:59657] mod_wsgi (pid=14399): Exception occurred processing WSGI script '/var/www/getip.com/ip/wsgi.py'.
[Tue Apr 22 11:44:21.340209 2014] [:error] [pid 14399:tid 139922307860224] [client 127.0.0.1:59657] Traceback (most recent call last):
[Tue Apr 22 11:44:21.340228 2014] [:error] [pid 14399:tid 139922307860224] [client 127.0.0.1:59657]   File "/var/www/getip.com/ip/wsgi.py", line 13, in <module>
[Tue Apr 22 11:44:21.340269 2014] [:error] [pid 14399:tid 139922307860224] [client 127.0.0.1:59657]     from django.core.wsgi import get_wsgi_application
[Tue Apr 22 11:44:21.340283 2014] [:error] [pid 14399:tid 139922307860224] [client 127.0.0.1:59657] ImportError: No module named django.core.wsgi
[Tue Apr 22 11:44:22.187876 2014] [:error] [pid 14399:tid 139922316252928] [client 127.0.0.1:59658] mod_wsgi (pid=14399): Target WSGI script '/var/www/getip.com/ip/wsgi.py' cannot be loaded as Python module.
[Tue Apr 22 11:44:22.187944 2014] [:error] [pid 14399:tid 139922316252928] [client 127.0.0.1:59658] mod_wsgi (pid=14399): Exception occurred processing WSGI script '/var/www/getip.com/ip/wsgi.py'.
[Tue Apr 22 11:44:22.188006 2014] [:error] [pid 14399:tid 139922316252928] [client 127.0.0.1:59658] Traceback (most recent call last):
[Tue Apr 22 11:44:22.188060 2014] [:error] [pid 14399:tid 139922316252928] [client 127.0.0.1:59658]   File "/var/www/getip.com/ip/wsgi.py", line 13, in <module>
[Tue Apr 22 11:44:22.188114 2014] [:error] [pid 14399:tid 139922316252928] [client 127.0.0.1:59658]     from django.core.wsgi import get_wsgi_application
[Tue Apr 22 11:44:22.188149 2014] [:error] [pid 14399:tid 139922316252928] [client 127.0.0.1:59658] ImportError: No module named django.core.wsgi
[Tue Apr 22 11:44:22.552428 2014] [:error] [pid 14398:tid 139922316252928] [client 127.0.0.1:59659] mod_wsgi (pid=14398): Target WSGI script '/var/www/getip.com/ip/wsgi.py' cannot be loaded as Python module.
[Tue Apr 22 11:44:22.552486 2014] [:error] [pid 14398:tid 139922316252928] [client 127.0.0.1:59659] mod_wsgi (pid=14398): Exception occurred processing WSGI script '/var/www/getip.com/ip/wsgi.py'.
[Tue Apr 22 11:44:22.552500 2014] [:error] [pid 14398:tid 139922316252928] [client 127.0.0.1:59659] Traceback (most recent call last):
[Tue Apr 22 11:44:22.552514 2014] [:error] [pid 14398:tid 139922316252928] [client 127.0.0.1:59659]   File "/var/www/getip.com/ip/wsgi.py", line 13, in <module>
[Tue Apr 22 11:44:22.552551 2014] [:error] [pid 14398:tid 139922316252928] [client 127.0.0.1:59659]     from django.core.wsgi import get_wsgi_application
[Tue Apr 22 11:44:22.552564 2014] [:error] [pid 14398:tid 139922316252928] [client 127.0.0.1:59659] ImportError: No module named django.core.wsgi
[Tue Apr 22 11:44:22.912343 2014] [:error] [pid 14398:tid 139922307860224] [client 127.0.0.1:59660] mod_wsgi (pid=14398): Target WSGI script '/var/www/getip.com/ip/wsgi.py' cannot be loaded as Python module.
[Tue Apr 22 11:44:22.912366 2014] [:error] [pid 14398:tid 139922307860224] [client 127.0.0.1:59660] mod_wsgi (pid=14398): Exception occurred processing WSGI script '/var/www/getip.com/ip/wsgi.py'.
[Tue Apr 22 11:44:22.912387 2014] [:error] [pid 14398:tid 139922307860224] [client 127.0.0.1:59660] Traceback (most recent call last):
[Tue Apr 22 11:44:22.912407 2014] [:error] [pid 14398:tid 139922307860224] [client 127.0.0.1:59660]   File "/var/www/getip.com/ip/wsgi.py", line 13, in <module>
[Tue Apr 22 11:44:22.912433 2014] [:error] [pid 14398:tid 139922307860224] [client 127.0.0.1:59660]     from django.core.wsgi import get_wsgi_application
[Tue Apr 22 11:44:22.912451 2014] [:error] [pid 14398:tid 139922307860224] [client 127.0.0.1:59660] ImportError: No module named django.core.wsgi
[Tue Apr 22 11:53:43.437152 2014] [:error] [pid 14778:tid 140520550754048] [client 127.0.0.1:59757] mod_wsgi (pid=14778): Exception occurred processing WSGI script '/var/www/getip.com/ip/wsgi.py'.
[Tue Apr 22 11:53:43.437223 2014] [:error] [pid 14778:tid 140520550754048] [client 127.0.0.1:59757] Traceback (most recent call last):
[Tue Apr 22 11:53:43.437243 2014] [:error] [pid 14778:tid 140520550754048] [client 127.0.0.1:59757]   File "/usr/local/lib/python3.3/dist-packages/django/conf/__init__.py", line 128, in __init__
[Tue Apr 22 11:53:43.437410 2014] [:error] [pid 14778:tid 140520550754048] [client 127.0.0.1:59757]     mod = importlib.import_module(self.SETTINGS_MODULE)
[Tue Apr 22 11:53:43.437423 2014] [:error] [pid 14778:tid 140520550754048] [client 127.0.0.1:59757]   File "/usr/lib/python3.3/importlib/__init__.py", line 90, in import_module
[Tue Apr 22 11:53:43.437511 2014] [:error] [pid 14778:tid 140520550754048] [client 127.0.0.1:59757]     return _bootstrap._gcd_import(name[level:], package, level)
[Tue Apr 22 11:53:43.437523 2014] [:error] [pid 14778:tid 140520550754048] [client 127.0.0.1:59757]   File "<frozen importlib._bootstrap>", line 1584, in _gcd_import
[Tue Apr 22 11:53:43.437535 2014] [:error] [pid 14778:tid 140520550754048] [client 127.0.0.1:59757]   File "<frozen importlib._bootstrap>", line 1565, in _find_and_load
[Tue Apr 22 11:53:43.437547 2014] [:error] [pid 14778:tid 140520550754048] [client 127.0.0.1:59757]   File "<frozen importlib._bootstrap>", line 1512, in _find_and_load_unlocked
[Tue Apr 22 11:53:43.437557 2014] [:error] [pid 14778:tid 140520550754048] [client 127.0.0.1:59757]   File "<frozen importlib._bootstrap>", line 313, in _call_with_frames_removed
[Tue Apr 22 11:53:43.437566 2014] [:error] [pid 14778:tid 140520550754048] [client 127.0.0.1:59757]   File "<frozen importlib._bootstrap>", line 1584, in _gcd_import
[Tue Apr 22 11:53:43.437575 2014] [:error] [pid 14778:tid 140520550754048] [client 127.0.0.1:59757]   File "<frozen importlib._bootstrap>", line 1565, in _find_and_load
[Tue Apr 22 11:53:43.437584 2014] [:error] [pid 14778:tid 140520550754048] [client 127.0.0.1:59757]   File "<frozen importlib._bootstrap>", line 1529, in _find_and_load_unlocked
[Tue Apr 22 11:53:43.437601 2014] [:error] [pid 14778:tid 140520550754048] [client 127.0.0.1:59757] ImportError: No module named 'ip'
[Tue Apr 22 11:53:43.437610 2014] [:error] [pid 14778:tid 140520550754048] [client 127.0.0.1:59757] 
[Tue Apr 22 11:53:43.437613 2014] [:error] [pid 14778:tid 140520550754048] [client 127.0.0.1:59757] During handling of the above exception, another exception occurred:
[Tue Apr 22 11:53:43.437615 2014] [:error] [pid 14778:tid 140520550754048] [client 127.0.0.1:59757] 
[Tue Apr 22 11:53:43.437621 2014] [:error] [pid 14778:tid 140520550754048] [client 127.0.0.1:59757] Traceback (most recent call last):
[Tue Apr 22 11:53:43.437630 2014] [:error] [pid 14778:tid 140520550754048] [client 127.0.0.1:59757]   File "/usr/local/lib/python3.3/dist-packages/django/core/handlers/wsgi.py", line 187, in __call__
[Tue Apr 22 11:53:43.437736 2014] [:error] [pid 14778:tid 140520550754048] [client 127.0.0.1:59757]     self.load_middleware()
[Tue Apr 22 11:53:43.437748 2014] [:error] [pid 14778:tid 140520550754048] [client 127.0.0.1:59757]   File "/usr/local/lib/python3.3/dist-packages/django/core/handlers/base.py", line 46, in load_middleware
[Tue Apr 22 11:53:43.437870 2014] [:error] [pid 14778:tid 140520550754048] [client 127.0.0.1:59757]     for middleware_path in settings.MIDDLEWARE_CLASSES:
[Tue Apr 22 11:53:43.437882 2014] [:error] [pid 14778:tid 140520550754048] [client 127.0.0.1:59757]   File "/usr/local/lib/python3.3/dist-packages/django/conf/__init__.py", line 54, in __getattr__
[Tue Apr 22 11:53:43.437899 2014] [:error] [pid 14778:tid 140520550754048] [client 127.0.0.1:59757]     self._setup(name)
[Tue Apr 22 11:53:43.437907 2014] [:error] [pid 14778:tid 140520550754048] [client 127.0.0.1:59757]   File "/usr/local/lib/python3.3/dist-packages/django/conf/__init__.py", line 49, in _setup
[Tue Apr 22 11:53:43.437920 2014] [:error] [pid 14778:tid 140520550754048] [client 127.0.0.1:59757]     self._wrapped = Settings(settings_module)
[Tue Apr 22 11:53:43.437928 2014] [:error] [pid 14778:tid 140520550754048] [client 127.0.0.1:59757]   File "/usr/local/lib/python3.3/dist-packages/django/conf/__init__.py", line 132, in __init__
[Tue Apr 22 11:53:43.437942 2014] [:error] [pid 14778:tid 140520550754048] [client 127.0.0.1:59757]     % (self.SETTINGS_MODULE, e)
[Tue Apr 22 11:53:43.437959 2014] [:error] [pid 14778:tid 140520550754048] [client 127.0.0.1:59757] ImportError: Could not import settings 'ip.settings' (Is it on sys.path? Is there an import error in the settings file?): No module named 'ip'
[Tue Apr 22 11:53:44.200749 2014] [:error] [pid 14777:tid 140520550754048] [client 127.0.0.1:59758] mod_wsgi (pid=14777): Exception occurred processing WSGI script '/var/www/getip.com/ip/wsgi.py'.
[Tue Apr 22 11:53:44.200826 2014] [:error] [pid 14777:tid 140520550754048] [client 127.0.0.1:59758] Traceback (most recent call last):
[Tue Apr 22 11:53:44.200846 2014] [:error] [pid 14777:tid 140520550754048] [client 127.0.0.1:59758]   File "/usr/local/lib/python3.3/dist-packages/django/conf/__init__.py", line 128, in __init__
[Tue Apr 22 11:53:44.200997 2014] [:error] [pid 14777:tid 140520550754048] [client 127.0.0.1:59758]     mod = importlib.import_module(self.SETTINGS_MODULE)
[Tue Apr 22 11:53:44.201009 2014] [:error] [pid 14777:tid 140520550754048] [client 127.0.0.1:59758]   File "/usr/lib/python3.3/importlib/__init__.py", line 90, in import_module
[Tue Apr 22 11:53:44.201092 2014] [:error] [pid 14777:tid 140520550754048] [client 127.0.0.1:59758]     return _bootstrap._gcd_import(name[level:], package, level)
[Tue Apr 22 11:53:44.201104 2014] [:error] [pid 14777:tid 140520550754048] [client 127.0.0.1:59758]   File "<frozen importlib._bootstrap>", line 1584, in _gcd_import
[Tue Apr 22 11:53:44.201115 2014] [:error] [pid 14777:tid 140520550754048] [client 127.0.0.1:59758]   File "<frozen importlib._bootstrap>", line 1565, in _find_and_load
[Tue Apr 22 11:53:44.201127 2014] [:error] [pid 14777:tid 140520550754048] [client 127.0.0.1:59758]   File "<frozen importlib._bootstrap>", line 1512, in _find_and_load_unlocked
[Tue Apr 22 11:53:44.201138 2014] [:error] [pid 14777:tid 140520550754048] [client 127.0.0.1:59758]   File "<frozen importlib._bootstrap>", line 313, in _call_with_frames_removed
[Tue Apr 22 11:53:44.201147 2014] [:error] [pid 14777:tid 140520550754048] [client 127.0.0.1:59758]   File "<frozen importlib._bootstrap>", line 1584, in _gcd_import
[Tue Apr 22 11:53:44.201156 2014] [:error] [pid 14777:tid 140520550754048] [client 127.0.0.1:59758]   File "<frozen importlib._bootstrap>", line 1565, in _find_and_load
[Tue Apr 22 11:53:44.201165 2014] [:error] [pid 14777:tid 140520550754048] [client 127.0.0.1:59758]   File "<frozen importlib._bootstrap>", line 1529, in _find_and_load_unlocked
[Tue Apr 22 11:53:44.201181 2014] [:error] [pid 14777:tid 140520550754048] [client 127.0.0.1:59758] ImportError: No module named 'ip'
[Tue Apr 22 11:53:44.201190 2014] [:error] [pid 14777:tid 140520550754048] [client 127.0.0.1:59758] 
[Tue Apr 22 11:53:44.201193 2014] [:error] [pid 14777:tid 140520550754048] [client 127.0.0.1:59758] During handling of the above exception, another exception occurred:
[Tue Apr 22 11:53:44.201196 2014] [:error] [pid 14777:tid 140520550754048] [client 127.0.0.1:59758] 
[Tue Apr 22 11:53:44.201202 2014] [:error] [pid 14777:tid 140520550754048] [client 127.0.0.1:59758] Traceback (most recent call last):
[Tue Apr 22 11:53:44.201211 2014] [:error] [pid 14777:tid 140520550754048] [client 127.0.0.1:59758]   File "/usr/local/lib/python3.3/dist-packages/django/core/handlers/wsgi.py", line 187, in __call__
[Tue Apr 22 11:53:44.201312 2014] [:error] [pid 14777:tid 140520550754048] [client 127.0.0.1:59758]     self.load_middleware()
[Tue Apr 22 11:53:44.201324 2014] [:error] [pid 14777:tid 140520550754048] [client 127.0.0.1:59758]   File "/usr/local/lib/python3.3/dist-packages/django/core/handlers/base.py", line 46, in load_middleware
[Tue Apr 22 11:53:44.201442 2014] [:error] [pid 14777:tid 140520550754048] [client 127.0.0.1:59758]     for middleware_path in settings.MIDDLEWARE_CLASSES:
[Tue Apr 22 11:53:44.201454 2014] [:error] [pid 14777:tid 140520550754048] [client 127.0.0.1:59758]   File "/usr/local/lib/python3.3/dist-packages/django/conf/__init__.py", line 54, in __getattr__
[Tue Apr 22 11:53:44.201471 2014] [:error] [pid 14777:tid 140520550754048] [client 127.0.0.1:59758]     self._setup(name)
[Tue Apr 22 11:53:44.201488 2014] [:error] [pid 14777:tid 140520550754048] [client 127.0.0.1:59758]   File "/usr/local/lib/python3.3/dist-packages/django/conf/__init__.py", line 49, in _setup
[Tue Apr 22 11:53:44.201502 2014] [:error] [pid 14777:tid 140520550754048] [client 127.0.0.1:59758]     self._wrapped = Settings(settings_module)
[Tue Apr 22 11:53:44.201510 2014] [:error] [pid 14777:tid 140520550754048] [client 127.0.0.1:59758]   File "/usr/local/lib/python3.3/dist-packages/django/conf/__init__.py", line 132, in __init__
[Tue Apr 22 11:53:44.201524 2014] [:error] [pid 14777:tid 140520550754048] [client 127.0.0.1:59758]     % (self.SETTINGS_MODULE, e)
[Tue Apr 22 11:53:44.201536 2014] [:error] [pid 14777:tid 140520550754048] [client 127.0.0.1:59758] ImportError: Could not import settings 'ip.settings' (Is it on sys.path? Is there an import error in the settings file?): No module named 'ip'
[Tue Apr 22 11:53:44.553058 2014] [:error] [pid 14777:tid 140520542361344] [client 127.0.0.1:59759] mod_wsgi (pid=14777): Exception occurred processing WSGI script '/var/www/getip.com/ip/wsgi.py'.
[Tue Apr 22 11:53:44.553179 2014] [:error] [pid 14777:tid 140520542361344] [client 127.0.0.1:59759] Traceback (most recent call last):
[Tue Apr 22 11:53:44.553213 2014] [:error] [pid 14777:tid 140520542361344] [client 127.0.0.1:59759]   File "/usr/local/lib/python3.3/dist-packages/django/conf/__init__.py", line 128, in __init__
[Tue Apr 22 11:53:44.553264 2014] [:error] [pid 14777:tid 140520542361344] [client 127.0.0.1:59759]     mod = importlib.import_module(self.SETTINGS_MODULE)
[Tue Apr 22 11:53:44.553287 2014] [:error] [pid 14777:tid 140520542361344] [client 127.0.0.1:59759]   File "/usr/lib/python3.3/importlib/__init__.py", line 90, in import_module
[Tue Apr 22 11:53:44.553323 2014] [:error] [pid 14777:tid 140520542361344] [client 127.0.0.1:59759]     return _bootstrap._gcd_import(name[level:], package, level)
[Tue Apr 22 11:53:44.553341 2014] [:error] [pid 14777:tid 140520542361344] [client 127.0.0.1:59759]   File "<frozen importlib._bootstrap>", line 1584, in _gcd_import
[Tue Apr 22 11:53:44.553366 2014] [:error] [pid 14777:tid 140520542361344] [client 127.0.0.1:59759]   File "<frozen importlib._bootstrap>", line 1565, in _find_and_load
[Tue Apr 22 11:53:44.553388 2014] [:error] [pid 14777:tid 140520542361344] [client 127.0.0.1:59759]   File "<frozen importlib._bootstrap>", line 1512, in _find_and_load_unlocked
[Tue Apr 22 11:53:44.553410 2014] [:error] [pid 14777:tid 140520542361344] [client 127.0.0.1:59759]   File "<frozen importlib._bootstrap>", line 313, in _call_with_frames_removed
[Tue Apr 22 11:53:44.553431 2014] [:error] [pid 14777:tid 140520542361344] [client 127.0.0.1:59759]   File "<frozen importlib._bootstrap>", line 1584, in _gcd_import
[Tue Apr 22 11:53:44.553451 2014] [:error] [pid 14777:tid 140520542361344] [client 127.0.0.1:59759]   File "<frozen importlib._bootstrap>", line 1565, in _find_and_load
[Tue Apr 22 11:53:44.553472 2014] [:error] [pid 14777:tid 140520542361344] [client 127.0.0.1:59759]   File "<frozen importlib._bootstrap>", line 1529, in _find_and_load_unlocked
[Tue Apr 22 11:53:44.553508 2014] [:error] [pid 14777:tid 140520542361344] [client 127.0.0.1:59759] ImportError: No module named 'ip'
[Tue Apr 22 11:53:44.553526 2014] [:error] [pid 14777:tid 140520542361344] [client 127.0.0.1:59759] 
[Tue Apr 22 11:53:44.553533 2014] [:error] [pid 14777:tid 140520542361344] [client 127.0.0.1:59759] During handling of the above exception, another exception occurred:
[Tue Apr 22 11:53:44.553540 2014] [:error] [pid 14777:tid 140520542361344] [client 127.0.0.1:59759] 
[Tue Apr 22 11:53:44.553554 2014] [:error] [pid 14777:tid 140520542361344] [client 127.0.0.1:59759] Traceback (most recent call last):
[Tue Apr 22 11:53:44.553575 2014] [:error] [pid 14777:tid 140520542361344] [client 127.0.0.1:59759]   File "/usr/local/lib/python3.3/dist-packages/django/core/handlers/wsgi.py", line 187, in __call__
[Tue Apr 22 11:53:44.553612 2014] [:error] [pid 14777:tid 140520542361344] [client 127.0.0.1:59759]     self.load_middleware()
[Tue Apr 22 11:53:44.553645 2014] [:error] [pid 14777:tid 140520542361344] [client 127.0.0.1:59759]   File "/usr/local/lib/python3.3/dist-packages/django/core/handlers/base.py", line 46, in load_middleware
[Tue Apr 22 11:53:44.553680 2014] [:error] [pid 14777:tid 140520542361344] [client 127.0.0.1:59759]     for middleware_path in settings.MIDDLEWARE_CLASSES:
[Tue Apr 22 11:53:44.553699 2014] [:error] [pid 14777:tid 140520542361344] [client 127.0.0.1:59759]   File "/usr/local/lib/python3.3/dist-packages/django/conf/__init__.py", line 54, in __getattr__
[Tue Apr 22 11:53:44.553730 2014] [:error] [pid 14777:tid 140520542361344] [client 127.0.0.1:59759]     self._setup(name)
[Tue Apr 22 11:53:44.553748 2014] [:error] [pid 14777:tid 140520542361344] [client 127.0.0.1:59759]   File "/usr/local/lib/python3.3/dist-packages/django/conf/__init__.py", line 49, in _setup
[Tue Apr 22 11:53:44.553778 2014] [:error] [pid 14777:tid 140520542361344] [client 127.0.0.1:59759]     self._wrapped = Settings(settings_module)
[Tue Apr 22 11:53:44.553796 2014] [:error] [pid 14777:tid 140520542361344] [client 127.0.0.1:59759]   File "/usr/local/lib/python3.3/dist-packages/django/conf/__init__.py", line 132, in __init__
[Tue Apr 22 11:53:44.553826 2014] [:error] [pid 14777:tid 140520542361344] [client 127.0.0.1:59759]     % (self.SETTINGS_MODULE, e)
[Tue Apr 22 11:53:44.553854 2014] [:error] [pid 14777:tid 140520542361344] [client 127.0.0.1:59759] ImportError: Could not import settings 'ip.settings' (Is it on sys.path? Is there an import error in the settings file?): No module named 'ip'
[Tue Apr 22 11:53:44.972483 2014] [:error] [pid 14777:tid 140520533968640] [client 127.0.0.1:59760] mod_wsgi (pid=14777): Exception occurred processing WSGI script '/var/www/getip.com/ip/wsgi.py'.
[Tue Apr 22 11:53:44.972537 2014] [:error] [pid 14777:tid 140520533968640] [client 127.0.0.1:59760] Traceback (most recent call last):
[Tue Apr 22 11:53:44.972557 2014] [:error] [pid 14777:tid 140520533968640] [client 127.0.0.1:59760]   File "/usr/local/lib/python3.3/dist-packages/django/conf/__init__.py", line 128, in __init__
[Tue Apr 22 11:53:44.972581 2014] [:error] [pid 14777:tid 140520533968640] [client 127.0.0.1:59760]     mod = importlib.import_module(self.SETTINGS_MODULE)
[Tue Apr 22 11:53:44.972591 2014] [:error] [pid 14777:tid 140520533968640] [client 127.0.0.1:59760]   File "/usr/lib/python3.3/importlib/__init__.py", line 90, in import_module
[Tue Apr 22 11:53:44.972606 2014] [:error] [pid 14777:tid 140520533968640] [client 127.0.0.1:59760]     return _bootstrap._gcd_import(name[level:], package, level)
[Tue Apr 22 11:53:44.972614 2014] [:error] [pid 14777:tid 140520533968640] [client 127.0.0.1:59760]   File "<frozen importlib._bootstrap>", line 1584, in _gcd_import
[Tue Apr 22 11:53:44.972626 2014] [:error] [pid 14777:tid 140520533968640] [client 127.0.0.1:59760]   File "<frozen importlib._bootstrap>", line 1565, in _find_and_load
[Tue Apr 22 11:53:44.972635 2014] [:error] [pid 14777:tid 140520533968640] [client 127.0.0.1:59760]   File "<frozen importlib._bootstrap>", line 1512, in _find_and_load_unlocked
[Tue Apr 22 11:53:44.972644 2014] [:error] [pid 14777:tid 140520533968640] [client 127.0.0.1:59760]   File "<frozen importlib._bootstrap>", line 313, in _call_with_frames_removed
[Tue Apr 22 11:53:44.972653 2014] [:error] [pid 14777:tid 140520533968640] [client 127.0.0.1:59760]   File "<frozen importlib._bootstrap>", line 1584, in _gcd_import
[Tue Apr 22 11:53:44.972662 2014] [:error] [pid 14777:tid 140520533968640] [client 127.0.0.1:59760]   File "<frozen importlib._bootstrap>", line 1565, in _find_and_load
[Tue Apr 22 11:53:44.972671 2014] [:error] [pid 14777:tid 140520533968640] [client 127.0.0.1:59760]   File "<frozen importlib._bootstrap>", line 1529, in _find_and_load_unlocked
[Tue Apr 22 11:53:44.972688 2014] [:error] [pid 14777:tid 140520533968640] [client 127.0.0.1:59760] ImportError: No module named 'ip'
[Tue Apr 22 11:53:44.972696 2014] [:error] [pid 14777:tid 140520533968640] [client 127.0.0.1:59760] 
[Tue Apr 22 11:53:44.972708 2014] [:error] [pid 14777:tid 140520533968640] [client 127.0.0.1:59760] During handling of the above exception, another exception occurred:
[Tue Apr 22 11:53:44.972711 2014] [:error] [pid 14777:tid 140520533968640] [client 127.0.0.1:59760] 
[Tue Apr 22 11:53:44.972717 2014] [:error] [pid 14777:tid 140520533968640] [client 127.0.0.1:59760] Traceback (most recent call last):
[Tue Apr 22 11:53:44.972727 2014] [:error] [pid 14777:tid 140520533968640] [client 127.0.0.1:59760]   File "/usr/local/lib/python3.3/dist-packages/django/core/handlers/wsgi.py", line 187, in __call__
[Tue Apr 22 11:53:44.972755 2014] [:error] [pid 14777:tid 140520533968640] [client 127.0.0.1:59760]     self.load_middleware()
[Tue Apr 22 11:53:44.972776 2014] [:error] [pid 14777:tid 140520533968640] [client 127.0.0.1:59760]   File "/usr/local/lib/python3.3/dist-packages/django/core/handlers/base.py", line 46, in load_middleware
[Tue Apr 22 11:53:44.972810 2014] [:error] [pid 14777:tid 140520533968640] [client 127.0.0.1:59760]     for middleware_path in settings.MIDDLEWARE_CLASSES:
[Tue Apr 22 11:53:44.972834 2014] [:error] [pid 14777:tid 140520533968640] [client 127.0.0.1:59760]   File "/usr/local/lib/python3.3/dist-packages/django/conf/__init__.py", line 54, in __getattr__
[Tue Apr 22 11:53:44.972848 2014] [:error] [pid 14777:tid 140520533968640] [client 127.0.0.1:59760]     self._setup(name)
[Tue Apr 22 11:53:44.972856 2014] [:error] [pid 14777:tid 140520533968640] [client 127.0.0.1:59760]   File "/usr/local/lib/python3.3/dist-packages/django/conf/__init__.py", line 49, in _setup
[Tue Apr 22 11:53:44.972869 2014] [:error] [pid 14777:tid 140520533968640] [client 127.0.0.1:59760]     self._wrapped = Settings(settings_module)
[Tue Apr 22 11:53:44.972877 2014] [:error] [pid 14777:tid 140520533968640] [client 127.0.0.1:59760]   File "/usr/local/lib/python3.3/dist-packages/django/conf/__init__.py", line 132, in __init__
[Tue Apr 22 11:53:44.972907 2014] [:error] [pid 14777:tid 140520533968640] [client 127.0.0.1:59760]     % (self.SETTINGS_MODULE, e)
[Tue Apr 22 11:53:44.972935 2014] [:error] [pid 14777:tid 140520533968640] [client 127.0.0.1:59760] ImportError: Could not import settings 'ip.settings' (Is it on sys.path? Is there an import error in the settings file?): No module named 'ip'
[Tue Apr 22 11:53:45.336061 2014] [:error] [pid 14777:tid 140520458286848] [client 127.0.0.1:59761] mod_wsgi (pid=14777): Exception occurred processing WSGI script '/var/www/getip.com/ip/wsgi.py'.
[Tue Apr 22 11:53:45.336174 2014] [:error] [pid 14777:tid 140520458286848] [client 127.0.0.1:59761] Traceback (most recent call last):
[Tue Apr 22 11:53:45.336218 2014] [:error] [pid 14777:tid 140520458286848] [client 127.0.0.1:59761]   File "/usr/local/lib/python3.3/dist-packages/django/conf/__init__.py", line 128, in __init__
[Tue Apr 22 11:53:45.336270 2014] [:error] [pid 14777:tid 140520458286848] [client 127.0.0.1:59761]     mod = importlib.import_module(self.SETTINGS_MODULE)
[Tue Apr 22 11:53:45.336292 2014] [:error] [pid 14777:tid 140520458286848] [client 127.0.0.1:59761]   File "/usr/lib/python3.3/importlib/__init__.py", line 90, in import_module
[Tue Apr 22 11:53:45.336329 2014] [:error] [pid 14777:tid 140520458286848] [client 127.0.0.1:59761]     return _bootstrap._gcd_import(name[level:], package, level)
[Tue Apr 22 11:53:45.336349 2014] [:error] [pid 14777:tid 140520458286848] [client 127.0.0.1:59761]   File "<frozen importlib._bootstrap>", line 1584, in _gcd_import
[Tue Apr 22 11:53:45.336375 2014] [:error] [pid 14777:tid 140520458286848] [client 127.0.0.1:59761]   File "<frozen importlib._bootstrap>", line 1565, in _find_and_load
[Tue Apr 22 11:53:45.336398 2014] [:error] [pid 14777:tid 140520458286848] [client 127.0.0.1:59761]   File "<frozen importlib._bootstrap>", line 1512, in _find_and_load_unlocked
[Tue Apr 22 11:53:45.336420 2014] [:error] [pid 14777:tid 140520458286848] [client 127.0.0.1:59761]   File "<frozen importlib._bootstrap>", line 313, in _call_with_frames_removed
[Tue Apr 22 11:53:45.336457 2014] [:error] [pid 14777:tid 140520458286848] [client 127.0.0.1:59761]   File "<frozen importlib._bootstrap>", line 1584, in _gcd_import
[Tue Apr 22 11:53:45.336478 2014] [:error] [pid 14777:tid 140520458286848] [client 127.0.0.1:59761]   File "<frozen importlib._bootstrap>", line 1565, in _find_and_load
[Tue Apr 22 11:53:45.336499 2014] [:error] [pid 14777:tid 140520458286848] [client 127.0.0.1:59761]   File "<frozen importlib._bootstrap>", line 1529, in _find_and_load_unlocked
[Tue Apr 22 11:53:45.336536 2014] [:error] [pid 14777:tid 140520458286848] [client 127.0.0.1:59761] ImportError: No module named 'ip'
[Tue Apr 22 11:53:45.336555 2014] [:error] [pid 14777:tid 140520458286848] [client 127.0.0.1:59761] 
[Tue Apr 22 11:53:45.336562 2014] [:error] [pid 14777:tid 140520458286848] [client 127.0.0.1:59761] During handling of the above exception, another exception occurred:
[Tue Apr 22 11:53:45.336571 2014] [:error] [pid 14777:tid 140520458286848] [client 127.0.0.1:59761] 
[Tue Apr 22 11:53:45.336601 2014] [:error] [pid 14777:tid 140520458286848] [client 127.0.0.1:59761] Traceback (most recent call last):
[Tue Apr 22 11:53:45.336639 2014] [:error] [pid 14777:tid 140520458286848] [client 127.0.0.1:59761]   File "/usr/local/lib/python3.3/dist-packages/django/core/handlers/wsgi.py", line 187, in __call__
[Tue Apr 22 11:53:45.336683 2014] [:error] [pid 14777:tid 140520458286848] [client 127.0.0.1:59761]     self.load_middleware()
[Tue Apr 22 11:53:45.336703 2014] [:error] [pid 14777:tid 140520458286848] [client 127.0.0.1:59761]   File "/usr/local/lib/python3.3/dist-packages/django/core/handlers/base.py", line 46, in load_middleware
[Tue Apr 22 11:53:45.336737 2014] [:error] [pid 14777:tid 140520458286848] [client 127.0.0.1:59761]     for middleware_path in settings.MIDDLEWARE_CLASSES:
[Tue Apr 22 11:53:45.336756 2014] [:error] [pid 14777:tid 140520458286848] [client 127.0.0.1:59761]   File "/usr/local/lib/python3.3/dist-packages/django/conf/__init__.py", line 54, in __getattr__
[Tue Apr 22 11:53:45.336788 2014] [:error] [pid 14777:tid 140520458286848] [client 127.0.0.1:59761]     self._setup(name)
[Tue Apr 22 11:53:45.336806 2014] [:error] [pid 14777:tid 140520458286848] [client 127.0.0.1:59761]   File "/usr/local/lib/python3.3/dist-packages/django/conf/__init__.py", line 49, in _setup
[Tue Apr 22 11:53:45.336837 2014] [:error] [pid 14777:tid 140520458286848] [client 127.0.0.1:59761]     self._wrapped = Settings(settings_module)
[Tue Apr 22 11:53:45.336855 2014] [:error] [pid 14777:tid 140520458286848] [client 127.0.0.1:59761]   File "/usr/local/lib/python3.3/dist-packages/django/conf/__init__.py", line 132, in __init__
[Tue Apr 22 11:53:45.336886 2014] [:error] [pid 14777:tid 140520458286848] [client 127.0.0.1:59761]     % (self.SETTINGS_MODULE, e)
[Tue Apr 22 11:53:45.336915 2014] [:error] [pid 14777:tid 140520458286848] [client 127.0.0.1:59761] ImportError: Could not import settings 'ip.settings' (Is it on sys.path? Is there an import error in the settings file?): No module named 'ip'
[Tue Apr 22 11:53:45.868655 2014] [:error] [pid 14777:tid 140520449894144] [client 127.0.0.1:59762] mod_wsgi (pid=14777): Exception occurred processing WSGI script '/var/www/getip.com/ip/wsgi.py'.
[Tue Apr 22 11:53:45.868710 2014] [:error] [pid 14777:tid 140520449894144] [client 127.0.0.1:59762] Traceback (most recent call last):
[Tue Apr 22 11:53:45.868731 2014] [:error] [pid 14777:tid 140520449894144] [client 127.0.0.1:59762]   File "/usr/local/lib/python3.3/dist-packages/django/conf/__init__.py", line 128, in __init__
[Tue Apr 22 11:53:45.868755 2014] [:error] [pid 14777:tid 140520449894144] [client 127.0.0.1:59762]     mod = importlib.import_module(self.SETTINGS_MODULE)
[Tue Apr 22 11:53:45.868764 2014] [:error] [pid 14777:tid 140520449894144] [client 127.0.0.1:59762]   File "/usr/lib/python3.3/importlib/__init__.py", line 90, in import_module
[Tue Apr 22 11:53:45.868780 2014] [:error] [pid 14777:tid 140520449894144] [client 127.0.0.1:59762]     return _bootstrap._gcd_import(name[level:], package, level)
[Tue Apr 22 11:53:45.868788 2014] [:error] [pid 14777:tid 140520449894144] [client 127.0.0.1:59762]   File "<frozen importlib._bootstrap>", line 1584, in _gcd_import
[Tue Apr 22 11:53:45.868817 2014] [:error] [pid 14777:tid 140520449894144] [client 127.0.0.1:59762]   File "<frozen importlib._bootstrap>", line 1565, in _find_and_load
[Tue Apr 22 11:53:45.868837 2014] [:error] [pid 14777:tid 140520449894144] [client 127.0.0.1:59762]   File "<frozen importlib._bootstrap>", line 1512, in _find_and_load_unlocked
[Tue Apr 22 11:53:45.868854 2014] [:error] [pid 14777:tid 140520449894144] [client 127.0.0.1:59762]   File "<frozen importlib._bootstrap>", line 313, in _call_with_frames_removed
[Tue Apr 22 11:53:45.868871 2014] [:error] [pid 14777:tid 140520449894144] [client 127.0.0.1:59762]   File "<frozen importlib._bootstrap>", line 1584, in _gcd_import
[Tue Apr 22 11:53:45.868888 2014] [:error] [pid 14777:tid 140520449894144] [client 127.0.0.1:59762]   File "<frozen importlib._bootstrap>", line 1565, in _find_and_load
[Tue Apr 22 11:53:45.868904 2014] [:error] [pid 14777:tid 140520449894144] [client 127.0.0.1:59762]   File "<frozen importlib._bootstrap>", line 1529, in _find_and_load_unlocked
[Tue Apr 22 11:53:45.868931 2014] [:error] [pid 14777:tid 140520449894144] [client 127.0.0.1:59762] ImportError: No module named 'ip'
[Tue Apr 22 11:53:45.868945 2014] [:error] [pid 14777:tid 140520449894144] [client 127.0.0.1:59762] 
[Tue Apr 22 11:53:45.868951 2014] [:error] [pid 14777:tid 140520449894144] [client 127.0.0.1:59762] During handling of the above exception, another exception occurred:
[Tue Apr 22 11:53:45.868955 2014] [:error] [pid 14777:tid 140520449894144] [client 127.0.0.1:59762] 
[Tue Apr 22 11:53:45.868966 2014] [:error] [pid 14777:tid 140520449894144] [client 127.0.0.1:59762] Traceback (most recent call last):
[Tue Apr 22 11:53:45.868982 2014] [:error] [pid 14777:tid 140520449894144] [client 127.0.0.1:59762]   File "/usr/local/lib/python3.3/dist-packages/django/core/handlers/wsgi.py", line 187, in __call__
[Tue Apr 22 11:53:45.869002 2014] [:error] [pid 14777:tid 140520449894144] [client 127.0.0.1:59762]     self.load_middleware()
[Tue Apr 22 11:53:45.869011 2014] [:error] [pid 14777:tid 140520449894144] [client 127.0.0.1:59762]   File "/usr/local/lib/python3.3/dist-packages/django/core/handlers/base.py", line 46, in load_middleware
[Tue Apr 22 11:53:45.869026 2014] [:error] [pid 14777:tid 140520449894144] [client 127.0.0.1:59762]     for middleware_path in settings.MIDDLEWARE_CLASSES:
[Tue Apr 22 11:53:45.869034 2014] [:error] [pid 14777:tid 140520449894144] [client 127.0.0.1:59762]   File "/usr/local/lib/python3.3/dist-packages/django/conf/__init__.py", line 54, in __getattr__
[Tue Apr 22 11:53:45.869048 2014] [:error] [pid 14777:tid 140520449894144] [client 127.0.0.1:59762]     self._setup(name)
[Tue Apr 22 11:53:45.869055 2014] [:error] [pid 14777:tid 140520449894144] [client 127.0.0.1:59762]   File "/usr/local/lib/python3.3/dist-packages/django/conf/__init__.py", line 49, in _setup
[Tue Apr 22 11:53:45.869069 2014] [:error] [pid 14777:tid 140520449894144] [client 127.0.0.1:59762]     self._wrapped = Settings(settings_module)
[Tue Apr 22 11:53:45.869077 2014] [:error] [pid 14777:tid 140520449894144] [client 127.0.0.1:59762]   File "/usr/local/lib/python3.3/dist-packages/django/conf/__init__.py", line 132, in __init__
[Tue Apr 22 11:53:45.869196 2014] [:error] [pid 14777:tid 140520449894144] [client 127.0.0.1:59762]     % (self.SETTINGS_MODULE, e)
[Tue Apr 22 11:53:45.869223 2014] [:error] [pid 14777:tid 140520449894144] [client 127.0.0.1:59762] ImportError: Could not import settings 'ip.settings' (Is it on sys.path? Is there an import error in the settings file?): No module named 'ip'
[Tue Apr 22 11:53:46.183448 2014] [:error] [pid 14777:tid 140520441501440] [client 127.0.0.1:59763] mod_wsgi (pid=14777): Exception occurred processing WSGI script '/var/www/getip.com/ip/wsgi.py'.
[Tue Apr 22 11:53:46.183508 2014] [:error] [pid 14777:tid 140520441501440] [client 127.0.0.1:59763] Traceback (most recent call last):
[Tue Apr 22 11:53:46.183528 2014] [:error] [pid 14777:tid 140520441501440] [client 127.0.0.1:59763]   File "/usr/local/lib/python3.3/dist-packages/django/conf/__init__.py", line 128, in __init__
[Tue Apr 22 11:53:46.183566 2014] [:error] [pid 14777:tid 140520441501440] [client 127.0.0.1:59763]     mod = importlib.import_module(self.SETTINGS_MODULE)
[Tue Apr 22 11:53:46.183597 2014] [:error] [pid 14777:tid 140520441501440] [client 127.0.0.1:59763]   File "/usr/lib/python3.3/importlib/__init__.py", line 90, in import_module
[Tue Apr 22 11:53:46.183639 2014] [:error] [pid 14777:tid 140520441501440] [client 127.0.0.1:59763]     return _bootstrap._gcd_import(name[level:], package, level)
[Tue Apr 22 11:53:46.183659 2014] [:error] [pid 14777:tid 140520441501440] [client 127.0.0.1:59763]   File "<frozen importlib._bootstrap>", line 1584, in _gcd_import
[Tue Apr 22 11:53:46.183686 2014] [:error] [pid 14777:tid 140520441501440] [client 127.0.0.1:59763]   File "<frozen importlib._bootstrap>", line 1565, in _find_and_load
[Tue Apr 22 11:53:46.183708 2014] [:error] [pid 14777:tid 140520441501440] [client 127.0.0.1:59763]   File "<frozen importlib._bootstrap>", line 1512, in _find_and_load_unlocked
[Tue Apr 22 11:53:46.183730 2014] [:error] [pid 14777:tid 140520441501440] [client 127.0.0.1:59763]   File "<frozen importlib._bootstrap>", line 313, in _call_with_frames_removed
[Tue Apr 22 11:53:46.183751 2014] [:error] [pid 14777:tid 140520441501440] [client 127.0.0.1:59763]   File "<frozen importlib._bootstrap>", line 1584, in _gcd_import
[Tue Apr 22 11:53:46.183772 2014] [:error] [pid 14777:tid 140520441501440] [client 127.0.0.1:59763]   File "<frozen importlib._bootstrap>", line 1565, in _find_and_load
[Tue Apr 22 11:53:46.183793 2014] [:error] [pid 14777:tid 140520441501440] [client 127.0.0.1:59763]   File "<frozen importlib._bootstrap>", line 1529, in _find_and_load_unlocked
[Tue Apr 22 11:53:46.183830 2014] [:error] [pid 14777:tid 140520441501440] [client 127.0.0.1:59763] ImportError: No module named 'ip'
[Tue Apr 22 11:53:46.183849 2014] [:error] [pid 14777:tid 140520441501440] [client 127.0.0.1:59763] 
[Tue Apr 22 11:53:46.183856 2014] [:error] [pid 14777:tid 140520441501440] [client 127.0.0.1:59763] During handling of the above exception, another exception occurred:
[Tue Apr 22 11:53:46.183863 2014] [:error] [pid 14777:tid 140520441501440] [client 127.0.0.1:59763] 
[Tue Apr 22 11:53:46.183877 2014] [:error] [pid 14777:tid 140520441501440] [client 127.0.0.1:59763] Traceback (most recent call last):
[Tue Apr 22 11:53:46.183897 2014] [:error] [pid 14777:tid 140520441501440] [client 127.0.0.1:59763]   File "/usr/local/lib/python3.3/dist-packages/django/core/handlers/wsgi.py", line 187, in __call__
[Tue Apr 22 11:53:46.183934 2014] [:error] [pid 14777:tid 140520441501440] [client 127.0.0.1:59763]     self.load_middleware()
[Tue Apr 22 11:53:46.183954 2014] [:error] [pid 14777:tid 140520441501440] [client 127.0.0.1:59763]   File "/usr/local/lib/python3.3/dist-packages/django/core/handlers/base.py", line 46, in load_middleware
[Tue Apr 22 11:53:46.183987 2014] [:error] [pid 14777:tid 140520441501440] [client 127.0.0.1:59763]     for middleware_path in settings.MIDDLEWARE_CLASSES:
[Tue Apr 22 11:53:46.184005 2014] [:error] [pid 14777:tid 140520441501440] [client 127.0.0.1:59763]   File "/usr/local/lib/python3.3/dist-packages/django/conf/__init__.py", line 54, in __getattr__
[Tue Apr 22 11:53:46.184036 2014] [:error] [pid 14777:tid 140520441501440] [client 127.0.0.1:59763]     self._setup(name)
[Tue Apr 22 11:53:46.184054 2014] [:error] [pid 14777:tid 140520441501440] [client 127.0.0.1:59763]   File "/usr/local/lib/python3.3/dist-packages/django/conf/__init__.py", line 49, in _setup
[Tue Apr 22 11:53:46.184084 2014] [:error] [pid 14777:tid 140520441501440] [client 127.0.0.1:59763]     self._wrapped = Settings(settings_module)
[Tue Apr 22 11:53:46.184102 2014] [:error] [pid 14777:tid 140520441501440] [client 127.0.0.1:59763]   File "/usr/local/lib/python3.3/dist-packages/django/conf/__init__.py", line 132, in __init__
[Tue Apr 22 11:53:46.184133 2014] [:error] [pid 14777:tid 140520441501440] [client 127.0.0.1:59763]     % (self.SETTINGS_MODULE, e)
[Tue Apr 22 11:53:46.184169 2014] [:error] [pid 14777:tid 140520441501440] [client 127.0.0.1:59763] ImportError: Could not import settings 'ip.settings' (Is it on sys.path? Is there an import error in the settings file?): No module named 'ip'
[Tue Apr 22 11:55:03.134724 2014] [:error] [pid 14932:tid 140634492999424] [client 127.0.0.1:59764] mod_wsgi (pid=14932): Exception occurred processing WSGI script '/var/www/getip.com/ip/wsgi.py'.
[Tue Apr 22 11:55:03.134800 2014] [:error] [pid 14932:tid 140634492999424] [client 127.0.0.1:59764] Traceback (most recent call last):
[Tue Apr 22 11:55:03.134834 2014] [:error] [pid 14932:tid 140634492999424] [client 127.0.0.1:59764]   File "/usr/local/lib/python3.3/dist-packages/django/conf/__init__.py", line 128, in __init__
[Tue Apr 22 11:55:03.134987 2014] [:error] [pid 14932:tid 140634492999424] [client 127.0.0.1:59764]     mod = importlib.import_module(self.SETTINGS_MODULE)
[Tue Apr 22 11:55:03.135000 2014] [:error] [pid 14932:tid 140634492999424] [client 127.0.0.1:59764]   File "/usr/lib/python3.3/importlib/__init__.py", line 90, in import_module
[Tue Apr 22 11:55:03.135083 2014] [:error] [pid 14932:tid 140634492999424] [client 127.0.0.1:59764]     return _bootstrap._gcd_import(name[level:], package, level)
[Tue Apr 22 11:55:03.135095 2014] [:error] [pid 14932:tid 140634492999424] [client 127.0.0.1:59764]   File "<frozen importlib._bootstrap>", line 1584, in _gcd_import
[Tue Apr 22 11:55:03.135106 2014] [:error] [pid 14932:tid 140634492999424] [client 127.0.0.1:59764]   File "<frozen importlib._bootstrap>", line 1565, in _find_and_load
[Tue Apr 22 11:55:03.135121 2014] [:error] [pid 14932:tid 140634492999424] [client 127.0.0.1:59764]   File "<frozen importlib._bootstrap>", line 1512, in _find_and_load_unlocked
[Tue Apr 22 11:55:03.135131 2014] [:error] [pid 14932:tid 140634492999424] [client 127.0.0.1:59764]   File "<frozen importlib._bootstrap>", line 313, in _call_with_frames_removed
[Tue Apr 22 11:55:03.135141 2014] [:error] [pid 14932:tid 140634492999424] [client 127.0.0.1:59764]   File "<frozen importlib._bootstrap>", line 1584, in _gcd_import
[Tue Apr 22 11:55:03.135150 2014] [:error] [pid 14932:tid 140634492999424] [client 127.0.0.1:59764]   File "<frozen importlib._bootstrap>", line 1565, in _find_and_load
[Tue Apr 22 11:55:03.135159 2014] [:error] [pid 14932:tid 140634492999424] [client 127.0.0.1:59764]   File "<frozen importlib._bootstrap>", line 1529, in _find_and_load_unlocked
[Tue Apr 22 11:55:03.135176 2014] [:error] [pid 14932:tid 140634492999424] [client 127.0.0.1:59764] ImportError: No module named 'ip'
[Tue Apr 22 11:55:03.135185 2014] [:error] [pid 14932:tid 140634492999424] [client 127.0.0.1:59764] 
[Tue Apr 22 11:55:03.135189 2014] [:error] [pid 14932:tid 140634492999424] [client 127.0.0.1:59764] During handling of the above exception, another exception occurred:
[Tue Apr 22 11:55:03.135192 2014] [:error] [pid 14932:tid 140634492999424] [client 127.0.0.1:59764] 
[Tue Apr 22 11:55:03.135198 2014] [:error] [pid 14932:tid 140634492999424] [client 127.0.0.1:59764] Traceback (most recent call last):
[Tue Apr 22 11:55:03.135207 2014] [:error] [pid 14932:tid 140634492999424] [client 127.0.0.1:59764]   File "/usr/local/lib/python3.3/dist-packages/django/core/handlers/wsgi.py", line 187, in __call__
[Tue Apr 22 11:55:03.135309 2014] [:error] [pid 14932:tid 140634492999424] [client 127.0.0.1:59764]     self.load_middleware()
[Tue Apr 22 11:55:03.135321 2014] [:error] [pid 14932:tid 140634492999424] [client 127.0.0.1:59764]   File "/usr/local/lib/python3.3/dist-packages/django/core/handlers/base.py", line 46, in load_middleware
[Tue Apr 22 11:55:03.135437 2014] [:error] [pid 14932:tid 140634492999424] [client 127.0.0.1:59764]     for middleware_path in settings.MIDDLEWARE_CLASSES:
[Tue Apr 22 11:55:03.135449 2014] [:error] [pid 14932:tid 140634492999424] [client 127.0.0.1:59764]   File "/usr/local/lib/python3.3/dist-packages/django/conf/__init__.py", line 54, in __getattr__
[Tue Apr 22 11:55:03.135483 2014] [:error] [pid 14932:tid 140634492999424] [client 127.0.0.1:59764]     self._setup(name)
[Tue Apr 22 11:55:03.135492 2014] [:error] [pid 14932:tid 140634492999424] [client 127.0.0.1:59764]   File "/usr/local/lib/python3.3/dist-packages/django/conf/__init__.py", line 49, in _setup
[Tue Apr 22 11:55:03.135506 2014] [:error] [pid 14932:tid 140634492999424] [client 127.0.0.1:59764]     self._wrapped = Settings(settings_module)
[Tue Apr 22 11:55:03.135513 2014] [:error] [pid 14932:tid 140634492999424] [client 127.0.0.1:59764]   File "/usr/local/lib/python3.3/dist-packages/django/conf/__init__.py", line 132, in __init__
[Tue Apr 22 11:55:03.135526 2014] [:error] [pid 14932:tid 140634492999424] [client 127.0.0.1:59764]     % (self.SETTINGS_MODULE, e)
[Tue Apr 22 11:55:03.135539 2014] [:error] [pid 14932:tid 140634492999424] [client 127.0.0.1:59764] ImportError: Could not import settings 'ip.settings' (Is it on sys.path? Is there an import error in the settings file?): No module named 'ip'
[Tue Apr 22 11:55:03.713895 2014] [:error] [pid 14932:tid 140634484606720] [client 127.0.0.1:59765] mod_wsgi (pid=14932): Exception occurred processing WSGI script '/var/www/getip.com/ip/wsgi.py'.
[Tue Apr 22 11:55:03.714010 2014] [:error] [pid 14932:tid 140634484606720] [client 127.0.0.1:59765] Traceback (most recent call last):
[Tue Apr 22 11:55:03.714076 2014] [:error] [pid 14932:tid 140634484606720] [client 127.0.0.1:59765]   File "/usr/local/lib/python3.3/dist-packages/django/conf/__init__.py", line 128, in __init__
[Tue Apr 22 11:55:03.714131 2014] [:error] [pid 14932:tid 140634484606720] [client 127.0.0.1:59765]     mod = importlib.import_module(self.SETTINGS_MODULE)
[Tue Apr 22 11:55:03.714152 2014] [:error] [pid 14932:tid 140634484606720] [client 127.0.0.1:59765]   File "/usr/lib/python3.3/importlib/__init__.py", line 90, in import_module
[Tue Apr 22 11:55:03.714186 2014] [:error] [pid 14932:tid 140634484606720] [client 127.0.0.1:59765]     return _bootstrap._gcd_import(name[level:], package, level)
[Tue Apr 22 11:55:03.714205 2014] [:error] [pid 14932:tid 140634484606720] [client 127.0.0.1:59765]   File "<frozen importlib._bootstrap>", line 1584, in _gcd_import
[Tue Apr 22 11:55:03.714230 2014] [:error] [pid 14932:tid 140634484606720] [client 127.0.0.1:59765]   File "<frozen importlib._bootstrap>", line 1565, in _find_and_load
[Tue Apr 22 11:55:03.714252 2014] [:error] [pid 14932:tid 140634484606720] [client 127.0.0.1:59765]   File "<frozen importlib._bootstrap>", line 1512, in _find_and_load_unlocked
[Tue Apr 22 11:55:03.714273 2014] [:error] [pid 14932:tid 140634484606720] [client 127.0.0.1:59765]   File "<frozen importlib._bootstrap>", line 313, in _call_with_frames_removed
[Tue Apr 22 11:55:03.714294 2014] [:error] [pid 14932:tid 140634484606720] [client 127.0.0.1:59765]   File "<frozen importlib._bootstrap>", line 1584, in _gcd_import
[Tue Apr 22 11:55:03.714314 2014] [:error] [pid 14932:tid 140634484606720] [client 127.0.0.1:59765]   File "<frozen importlib._bootstrap>", line 1565, in _find_and_load
[Tue Apr 22 11:55:03.714335 2014] [:error] [pid 14932:tid 140634484606720] [client 127.0.0.1:59765]   File "<frozen importlib._bootstrap>", line 1529, in _find_and_load_unlocked
[Tue Apr 22 11:55:03.714371 2014] [:error] [pid 14932:tid 140634484606720] [client 127.0.0.1:59765] ImportError: No module named 'ip'
[Tue Apr 22 11:55:03.714390 2014] [:error] [pid 14932:tid 140634484606720] [client 127.0.0.1:59765] 
[Tue Apr 22 11:55:03.714397 2014] [:error] [pid 14932:tid 140634484606720] [client 127.0.0.1:59765] During handling of the above exception, another exception occurred:
[Tue Apr 22 11:55:03.714403 2014] [:error] [pid 14932:tid 140634484606720] [client 127.0.0.1:59765] 
[Tue Apr 22 11:55:03.714417 2014] [:error] [pid 14932:tid 140634484606720] [client 127.0.0.1:59765] Traceback (most recent call last):
[Tue Apr 22 11:55:03.714438 2014] [:error] [pid 14932:tid 140634484606720] [client 127.0.0.1:59765]   File "/usr/local/lib/python3.3/dist-packages/django/core/handlers/wsgi.py", line 187, in __call__
[Tue Apr 22 11:55:03.714528 2014] [:error] [pid 14932:tid 140634484606720] [client 127.0.0.1:59765]     self.load_middleware()
[Tue Apr 22 11:55:03.714568 2014] [:error] [pid 14932:tid 140634484606720] [client 127.0.0.1:59765]   File "/usr/local/lib/python3.3/dist-packages/django/core/handlers/base.py", line 46, in load_middleware
[Tue Apr 22 11:55:03.714628 2014] [:error] [pid 14932:tid 140634484606720] [client 127.0.0.1:59765]     for middleware_path in settings.MIDDLEWARE_CLASSES:
[Tue Apr 22 11:55:03.714645 2014] [:error] [pid 14932:tid 140634484606720] [client 127.0.0.1:59765]   File "/usr/local/lib/python3.3/dist-packages/django/conf/__init__.py", line 54, in __getattr__
[Tue Apr 22 11:55:03.714668 2014] [:error] [pid 14932:tid 140634484606720] [client 127.0.0.1:59765]     self._setup(name)
[Tue Apr 22 11:55:03.714686 2014] [:error] [pid 14932:tid 140634484606720] [client 127.0.0.1:59765]   File "/usr/local/lib/python3.3/dist-packages/django/conf/__init__.py", line 49, in _setup
[Tue Apr 22 11:55:03.714713 2014] [:error] [pid 14932:tid 140634484606720] [client 127.0.0.1:59765]     self._wrapped = Settings(settings_module)
[Tue Apr 22 11:55:03.714730 2014] [:error] [pid 14932:tid 140634484606720] [client 127.0.0.1:59765]   File "/usr/local/lib/python3.3/dist-packages/django/conf/__init__.py", line 132, in __init__
[Tue Apr 22 11:55:03.714758 2014] [:error] [pid 14932:tid 140634484606720] [client 127.0.0.1:59765]     % (self.SETTINGS_MODULE, e)
[Tue Apr 22 11:55:03.714783 2014] [:error] [pid 14932:tid 140634484606720] [client 127.0.0.1:59765] ImportError: Could not import settings 'ip.settings' (Is it on sys.path? Is there an import error in the settings file?): No module named 'ip'
[Tue Apr 22 11:55:04.093083 2014] [:error] [pid 14932:tid 140634476214016] [client 127.0.0.1:59766] mod_wsgi (pid=14932): Exception occurred processing WSGI script '/var/www/getip.com/ip/wsgi.py'.
[Tue Apr 22 11:55:04.093197 2014] [:error] [pid 14932:tid 140634476214016] [client 127.0.0.1:59766] Traceback (most recent call last):
[Tue Apr 22 11:55:04.093240 2014] [:error] [pid 14932:tid 140634476214016] [client 127.0.0.1:59766]   File "/usr/local/lib/python3.3/dist-packages/django/conf/__init__.py", line 128, in __init__
[Tue Apr 22 11:55:04.093290 2014] [:error] [pid 14932:tid 140634476214016] [client 127.0.0.1:59766]     mod = importlib.import_module(self.SETTINGS_MODULE)
[Tue Apr 22 11:55:04.093312 2014] [:error] [pid 14932:tid 140634476214016] [client 127.0.0.1:59766]   File "/usr/lib/python3.3/importlib/__init__.py", line 90, in import_module
[Tue Apr 22 11:55:04.093346 2014] [:error] [pid 14932:tid 140634476214016] [client 127.0.0.1:59766]     return _bootstrap._gcd_import(name[level:], package, level)
[Tue Apr 22 11:55:04.093365 2014] [:error] [pid 14932:tid 140634476214016] [client 127.0.0.1:59766]   File "<frozen importlib._bootstrap>", line 1584, in _gcd_import
[Tue Apr 22 11:55:04.093391 2014] [:error] [pid 14932:tid 140634476214016] [client 127.0.0.1:59766]   File "<frozen importlib._bootstrap>", line 1565, in _find_and_load
[Tue Apr 22 11:55:04.093413 2014] [:error] [pid 14932:tid 140634476214016] [client 127.0.0.1:59766]   File "<frozen importlib._bootstrap>", line 1512, in _find_and_load_unlocked
[Tue Apr 22 11:55:04.093435 2014] [:error] [pid 14932:tid 140634476214016] [client 127.0.0.1:59766]   File "<frozen importlib._bootstrap>", line 313, in _call_with_frames_removed
[Tue Apr 22 11:55:04.093456 2014] [:error] [pid 14932:tid 140634476214016] [client 127.0.0.1:59766]   File "<frozen importlib._bootstrap>", line 1584, in _gcd_import
[Tue Apr 22 11:55:04.093476 2014] [:error] [pid 14932:tid 140634476214016] [client 127.0.0.1:59766]   File "<frozen importlib._bootstrap>", line 1565, in _find_and_load
[Tue Apr 22 11:55:04.093497 2014] [:error] [pid 14932:tid 140634476214016] [client 127.0.0.1:59766]   File "<frozen importlib._bootstrap>", line 1529, in _find_and_load_unlocked
[Tue Apr 22 11:55:04.093533 2014] [:error] [pid 14932:tid 140634476214016] [client 127.0.0.1:59766] ImportError: No module named 'ip'
[Tue Apr 22 11:55:04.093552 2014] [:error] [pid 14932:tid 140634476214016] [client 127.0.0.1:59766] 
[Tue Apr 22 11:55:04.093573 2014] [:error] [pid 14932:tid 140634476214016] [client 127.0.0.1:59766] During handling of the above exception, another exception occurred:
[Tue Apr 22 11:55:04.093580 2014] [:error] [pid 14932:tid 140634476214016] [client 127.0.0.1:59766] 
[Tue Apr 22 11:55:04.093595 2014] [:error] [pid 14932:tid 140634476214016] [client 127.0.0.1:59766] Traceback (most recent call last):
[Tue Apr 22 11:55:04.093617 2014] [:error] [pid 14932:tid 140634476214016] [client 127.0.0.1:59766]   File "/usr/local/lib/python3.3/dist-packages/django/core/handlers/wsgi.py", line 187, in __call__
[Tue Apr 22 11:55:04.093654 2014] [:error] [pid 14932:tid 140634476214016] [client 127.0.0.1:59766]     self.load_middleware()
[Tue Apr 22 11:55:04.093673 2014] [:error] [pid 14932:tid 140634476214016] [client 127.0.0.1:59766]   File "/usr/local/lib/python3.3/dist-packages/django/core/handlers/base.py", line 46, in load_middleware
[Tue Apr 22 11:55:04.093705 2014] [:error] [pid 14932:tid 140634476214016] [client 127.0.0.1:59766]     for middleware_path in settings.MIDDLEWARE_CLASSES:
[Tue Apr 22 11:55:04.093723 2014] [:error] [pid 14932:tid 140634476214016] [client 127.0.0.1:59766]   File "/usr/local/lib/python3.3/dist-packages/django/conf/__init__.py", line 54, in __getattr__
[Tue Apr 22 11:55:04.093753 2014] [:error] [pid 14932:tid 140634476214016] [client 127.0.0.1:59766]     self._setup(name)
[Tue Apr 22 11:55:04.093771 2014] [:error] [pid 14932:tid 140634476214016] [client 127.0.0.1:59766]   File "/usr/local/lib/python3.3/dist-packages/django/conf/__init__.py", line 49, in _setup
[Tue Apr 22 11:55:04.093800 2014] [:error] [pid 14932:tid 140634476214016] [client 127.0.0.1:59766]     self._wrapped = Settings(settings_module)
[Tue Apr 22 11:55:04.093818 2014] [:error] [pid 14932:tid 140634476214016] [client 127.0.0.1:59766]   File "/usr/local/lib/python3.3/dist-packages/django/conf/__init__.py", line 132, in __init__
[Tue Apr 22 11:55:04.093847 2014] [:error] [pid 14932:tid 140634476214016] [client 127.0.0.1:59766]     % (self.SETTINGS_MODULE, e)
[Tue Apr 22 11:55:04.093876 2014] [:error] [pid 14932:tid 140634476214016] [client 127.0.0.1:59766] ImportError: Could not import settings 'ip.settings' (Is it on sys.path? Is there an import error in the settings file?): No module named 'ip'
[Tue Apr 22 11:55:04.331780 2014] [:error] [pid 14932:tid 140634467821312] [client 127.0.0.1:59767] mod_wsgi (pid=14932): Exception occurred processing WSGI script '/var/www/getip.com/ip/wsgi.py'.
[Tue Apr 22 11:55:04.331837 2014] [:error] [pid 14932:tid 140634467821312] [client 127.0.0.1:59767] Traceback (most recent call last):
[Tue Apr 22 11:55:04.331858 2014] [:error] [pid 14932:tid 140634467821312] [client 127.0.0.1:59767]   File "/usr/local/lib/python3.3/dist-packages/django/conf/__init__.py", line 128, in __init__
[Tue Apr 22 11:55:04.331882 2014] [:error] [pid 14932:tid 140634467821312] [client 127.0.0.1:59767]     mod = importlib.import_module(self.SETTINGS_MODULE)
[Tue Apr 22 11:55:04.331891 2014] [:error] [pid 14932:tid 140634467821312] [client 127.0.0.1:59767]   File "/usr/lib/python3.3/importlib/__init__.py", line 90, in import_module
[Tue Apr 22 11:55:04.331907 2014] [:error] [pid 14932:tid 140634467821312] [client 127.0.0.1:59767]     return _bootstrap._gcd_import(name[level:], package, level)
[Tue Apr 22 11:55:04.331915 2014] [:error] [pid 14932:tid 140634467821312] [client 127.0.0.1:59767]   File "<frozen importlib._bootstrap>", line 1584, in _gcd_import
[Tue Apr 22 11:55:04.331926 2014] [:error] [pid 14932:tid 140634467821312] [client 127.0.0.1:59767]   File "<frozen importlib._bootstrap>", line 1565, in _find_and_load
[Tue Apr 22 11:55:04.331936 2014] [:error] [pid 14932:tid 140634467821312] [client 127.0.0.1:59767]   File "<frozen importlib._bootstrap>", line 1512, in _find_and_load_unlocked
[Tue Apr 22 11:55:04.331945 2014] [:error] [pid 14932:tid 140634467821312] [client 127.0.0.1:59767]   File "<frozen importlib._bootstrap>", line 313, in _call_with_frames_removed
[Tue Apr 22 11:55:04.331966 2014] [:error] [pid 14932:tid 140634467821312] [client 127.0.0.1:59767]   File "<frozen importlib._bootstrap>", line 1584, in _gcd_import
[Tue Apr 22 11:55:04.331975 2014] [:error] [pid 14932:tid 140634467821312] [client 127.0.0.1:59767]   File "<frozen importlib._bootstrap>", line 1565, in _find_and_load
[Tue Apr 22 11:55:04.331984 2014] [:error] [pid 14932:tid 140634467821312] [client 127.0.0.1:59767]   File "<frozen importlib._bootstrap>", line 1529, in _find_and_load_unlocked
[Tue Apr 22 11:55:04.332002 2014] [:error] [pid 14932:tid 140634467821312] [client 127.0.0.1:59767] ImportError: No module named 'ip'
[Tue Apr 22 11:55:04.332011 2014] [:error] [pid 14932:tid 140634467821312] [client 127.0.0.1:59767] 
[Tue Apr 22 11:55:04.332014 2014] [:error] [pid 14932:tid 140634467821312] [client 127.0.0.1:59767] During handling of the above exception, another exception occurred:
[Tue Apr 22 11:55:04.332016 2014] [:error] [pid 14932:tid 140634467821312] [client 127.0.0.1:59767] 
[Tue Apr 22 11:55:04.332022 2014] [:error] [pid 14932:tid 140634467821312] [client 127.0.0.1:59767] Traceback (most recent call last):
[Tue Apr 22 11:55:04.332032 2014] [:error] [pid 14932:tid 140634467821312] [client 127.0.0.1:59767]   File "/usr/local/lib/python3.3/dist-packages/django/core/handlers/wsgi.py", line 187, in __call__
[Tue Apr 22 11:55:04.332048 2014] [:error] [pid 14932:tid 140634467821312] [client 127.0.0.1:59767]     self.load_middleware()
[Tue Apr 22 11:55:04.332057 2014] [:error] [pid 14932:tid 140634467821312] [client 127.0.0.1:59767]   File "/usr/local/lib/python3.3/dist-packages/django/core/handlers/base.py", line 46, in load_middleware
[Tue Apr 22 11:55:04.332071 2014] [:error] [pid 14932:tid 140634467821312] [client 127.0.0.1:59767]     for middleware_path in settings.MIDDLEWARE_CLASSES:
[Tue Apr 22 11:55:04.332079 2014] [:error] [pid 14932:tid 140634467821312] [client 127.0.0.1:59767]   File "/usr/local/lib/python3.3/dist-packages/django/conf/__init__.py", line 54, in __getattr__
[Tue Apr 22 11:55:04.332092 2014] [:error] [pid 14932:tid 140634467821312] [client 127.0.0.1:59767]     self._setup(name)
[Tue Apr 22 11:55:04.332100 2014] [:error] [pid 14932:tid 140634467821312] [client 127.0.0.1:59767]   File "/usr/local/lib/python3.3/dist-packages/django/conf/__init__.py", line 49, in _setup
[Tue Apr 22 11:55:04.332113 2014] [:error] [pid 14932:tid 140634467821312] [client 127.0.0.1:59767]     self._wrapped = Settings(settings_module)
[Tue Apr 22 11:55:04.332120 2014] [:error] [pid 14932:tid 140634467821312] [client 127.0.0.1:59767]   File "/usr/local/lib/python3.3/dist-packages/django/conf/__init__.py", line 132, in __init__
[Tue Apr 22 11:55:04.332133 2014] [:error] [pid 14932:tid 140634467821312] [client 127.0.0.1:59767]     % (self.SETTINGS_MODULE, e)
[Tue Apr 22 11:55:04.332145 2014] [:error] [pid 14932:tid 140634467821312] [client 127.0.0.1:59767] ImportError: Could not import settings 'ip.settings' (Is it on sys.path? Is there an import error in the settings file?): No module named 'ip'
[Tue Apr 22 11:55:04.594778 2014] [:error] [pid 14932:tid 140634459428608] [client 127.0.0.1:59768] mod_wsgi (pid=14932): Exception occurred processing WSGI script '/var/www/getip.com/ip/wsgi.py'.
[Tue Apr 22 11:55:04.594849 2014] [:error] [pid 14932:tid 140634459428608] [client 127.0.0.1:59768] Traceback (most recent call last):
[Tue Apr 22 11:55:04.594870 2014] [:error] [pid 14932:tid 140634459428608] [client 127.0.0.1:59768]   File "/usr/local/lib/python3.3/dist-packages/django/conf/__init__.py", line 128, in __init__
[Tue Apr 22 11:55:04.594896 2014] [:error] [pid 14932:tid 140634459428608] [client 127.0.0.1:59768]     mod = importlib.import_module(self.SETTINGS_MODULE)
[Tue Apr 22 11:55:04.594905 2014] [:error] [pid 14932:tid 140634459428608] [client 127.0.0.1:59768]   File "/usr/lib/python3.3/importlib/__init__.py", line 90, in import_module
[Tue Apr 22 11:55:04.594921 2014] [:error] [pid 14932:tid 140634459428608] [client 127.0.0.1:59768]     return _bootstrap._gcd_import(name[level:], package, level)
[Tue Apr 22 11:55:04.594938 2014] [:error] [pid 14932:tid 140634459428608] [client 127.0.0.1:59768]   File "<frozen importlib._bootstrap>", line 1584, in _gcd_import
[Tue Apr 22 11:55:04.594951 2014] [:error] [pid 14932:tid 140634459428608] [client 127.0.0.1:59768]   File "<frozen importlib._bootstrap>", line 1565, in _find_and_load
[Tue Apr 22 11:55:04.594960 2014] [:error] [pid 14932:tid 140634459428608] [client 127.0.0.1:59768]   File "<frozen importlib._bootstrap>", line 1512, in _find_and_load_unlocked
[Tue Apr 22 11:55:04.594970 2014] [:error] [pid 14932:tid 140634459428608] [client 127.0.0.1:59768]   File "<frozen importlib._bootstrap>", line 313, in _call_with_frames_removed
[Tue Apr 22 11:55:04.594978 2014] [:error] [pid 14932:tid 140634459428608] [client 127.0.0.1:59768]   File "<frozen importlib._bootstrap>", line 1584, in _gcd_import
[Tue Apr 22 11:55:04.594987 2014] [:error] [pid 14932:tid 140634459428608] [client 127.0.0.1:59768]   File "<frozen importlib._bootstrap>", line 1565, in _find_and_load
[Tue Apr 22 11:55:04.594996 2014] [:error] [pid 14932:tid 140634459428608] [client 127.0.0.1:59768]   File "<frozen importlib._bootstrap>", line 1529, in _find_and_load_unlocked
[Tue Apr 22 11:55:04.595013 2014] [:error] [pid 14932:tid 140634459428608] [client 127.0.0.1:59768] ImportError: No module named 'ip'
[Tue Apr 22 11:55:04.595021 2014] [:error] [pid 14932:tid 140634459428608] [client 127.0.0.1:59768] 
[Tue Apr 22 11:55:04.595025 2014] [:error] [pid 14932:tid 140634459428608] [client 127.0.0.1:59768] During handling of the above exception, another exception occurred:
[Tue Apr 22 11:55:04.595027 2014] [:error] [pid 14932:tid 140634459428608] [client 127.0.0.1:59768] 
[Tue Apr 22 11:55:04.595033 2014] [:error] [pid 14932:tid 140634459428608] [client 127.0.0.1:59768] Traceback (most recent call last):
[Tue Apr 22 11:55:04.595043 2014] [:error] [pid 14932:tid 140634459428608] [client 127.0.0.1:59768]   File "/usr/local/lib/python3.3/dist-packages/django/core/handlers/wsgi.py", line 187, in __call__
[Tue Apr 22 11:55:04.595059 2014] [:error] [pid 14932:tid 140634459428608] [client 127.0.0.1:59768]     self.load_middleware()
[Tue Apr 22 11:55:04.595068 2014] [:error] [pid 14932:tid 140634459428608] [client 127.0.0.1:59768]   File "/usr/local/lib/python3.3/dist-packages/django/core/handlers/base.py", line 46, in load_middleware
[Tue Apr 22 11:55:04.595082 2014] [:error] [pid 14932:tid 140634459428608] [client 127.0.0.1:59768]     for middleware_path in settings.MIDDLEWARE_CLASSES:
[Tue Apr 22 11:55:04.595090 2014] [:error] [pid 14932:tid 140634459428608] [client 127.0.0.1:59768]   File "/usr/local/lib/python3.3/dist-packages/django/conf/__init__.py", line 54, in __getattr__
[Tue Apr 22 11:55:04.595103 2014] [:error] [pid 14932:tid 140634459428608] [client 127.0.0.1:59768]     self._setup(name)
[Tue Apr 22 11:55:04.595111 2014] [:error] [pid 14932:tid 140634459428608] [client 127.0.0.1:59768]   File "/usr/local/lib/python3.3/dist-packages/django/conf/__init__.py", line 49, in _setup
[Tue Apr 22 11:55:04.595124 2014] [:error] [pid 14932:tid 140634459428608] [client 127.0.0.1:59768]     self._wrapped = Settings(settings_module)
[Tue Apr 22 11:55:04.595132 2014] [:error] [pid 14932:tid 140634459428608] [client 127.0.0.1:59768]   File "/usr/local/lib/python3.3/dist-packages/django/conf/__init__.py", line 132, in __init__
[Tue Apr 22 11:55:04.595145 2014] [:error] [pid 14932:tid 140634459428608] [client 127.0.0.1:59768]     % (self.SETTINGS_MODULE, e)
[Tue Apr 22 11:55:04.595156 2014] [:error] [pid 14932:tid 140634459428608] [client 127.0.0.1:59768] ImportError: Could not import settings 'ip.settings' (Is it on sys.path? Is there an import error in the settings file?): No module named 'ip'
[Tue Apr 22 11:58:53.744916 2014] [:error] [pid 15084:tid 140706668533504] [client 127.0.0.1:59826] mod_wsgi (pid=15084): Exception occurred processing WSGI script '/var/www/getip.com/ip/wsgi.py'.
[Tue Apr 22 11:58:53.744995 2014] [:error] [pid 15084:tid 140706668533504] [client 127.0.0.1:59826] Traceback (most recent call last):
[Tue Apr 22 11:58:53.745034 2014] [:error] [pid 15084:tid 140706668533504] [client 127.0.0.1:59826]   File "/usr/local/lib/python3.3/dist-packages/django/conf/__init__.py", line 128, in __init__
[Tue Apr 22 11:58:53.745190 2014] [:error] [pid 15084:tid 140706668533504] [client 127.0.0.1:59826]     mod = importlib.import_module(self.SETTINGS_MODULE)
[Tue Apr 22 11:58:53.745207 2014] [:error] [pid 15084:tid 140706668533504] [client 127.0.0.1:59826]   File "/usr/lib/python3.3/importlib/__init__.py", line 90, in import_module
[Tue Apr 22 11:58:53.745293 2014] [:error] [pid 15084:tid 140706668533504] [client 127.0.0.1:59826]     return _bootstrap._gcd_import(name[level:], package, level)
[Tue Apr 22 11:58:53.745309 2014] [:error] [pid 15084:tid 140706668533504] [client 127.0.0.1:59826]   File "<frozen importlib._bootstrap>", line 1584, in _gcd_import
[Tue Apr 22 11:58:53.745324 2014] [:error] [pid 15084:tid 140706668533504] [client 127.0.0.1:59826]   File "<frozen importlib._bootstrap>", line 1565, in _find_and_load
[Tue Apr 22 11:58:53.745340 2014] [:error] [pid 15084:tid 140706668533504] [client 127.0.0.1:59826]   File "<frozen importlib._bootstrap>", line 1512, in _find_and_load_unlocked
[Tue Apr 22 11:58:53.745353 2014] [:error] [pid 15084:tid 140706668533504] [client 127.0.0.1:59826]   File "<frozen importlib._bootstrap>", line 313, in _call_with_frames_removed
[Tue Apr 22 11:58:53.745367 2014] [:error] [pid 15084:tid 140706668533504] [client 127.0.0.1:59826]   File "<frozen importlib._bootstrap>", line 1584, in _gcd_import
[Tue Apr 22 11:58:53.745380 2014] [:error] [pid 15084:tid 140706668533504] [client 127.0.0.1:59826]   File "<frozen importlib._bootstrap>", line 1565, in _find_and_load
[Tue Apr 22 11:58:53.745393 2014] [:error] [pid 15084:tid 140706668533504] [client 127.0.0.1:59826]   File "<frozen importlib._bootstrap>", line 1529, in _find_and_load_unlocked
[Tue Apr 22 11:58:53.745414 2014] [:error] [pid 15084:tid 140706668533504] [client 127.0.0.1:59826] ImportError: No module named 'ip'
[Tue Apr 22 11:58:53.745427 2014] [:error] [pid 15084:tid 140706668533504] [client 127.0.0.1:59826] 
[Tue Apr 22 11:58:53.745433 2014] [:error] [pid 15084:tid 140706668533504] [client 127.0.0.1:59826] During handling of the above exception, another exception occurred:
[Tue Apr 22 11:58:53.745437 2014] [:error] [pid 15084:tid 140706668533504] [client 127.0.0.1:59826] 
[Tue Apr 22 11:58:53.745444 2014] [:error] [pid 15084:tid 140706668533504] [client 127.0.0.1:59826] Traceback (most recent call last):
[Tue Apr 22 11:58:53.745456 2014] [:error] [pid 15084:tid 140706668533504] [client 127.0.0.1:59826]   File "/usr/local/lib/python3.3/dist-packages/django/core/handlers/wsgi.py", line 187, in __call__
[Tue Apr 22 11:58:53.745563 2014] [:error] [pid 15084:tid 140706668533504] [client 127.0.0.1:59826]     self.load_middleware()
[Tue Apr 22 11:58:53.745579 2014] [:error] [pid 15084:tid 140706668533504] [client 127.0.0.1:59826]   File "/usr/local/lib/python3.3/dist-packages/django/core/handlers/base.py", line 46, in load_middleware
[Tue Apr 22 11:58:53.745706 2014] [:error] [pid 15084:tid 140706668533504] [client 127.0.0.1:59826]     for middleware_path in settings.MIDDLEWARE_CLASSES:
[Tue Apr 22 11:58:53.745725 2014] [:error] [pid 15084:tid 140706668533504] [client 127.0.0.1:59826]   File "/usr/local/lib/python3.3/dist-packages/django/conf/__init__.py", line 54, in __getattr__
[Tue Apr 22 11:58:53.745759 2014] [:error] [pid 15084:tid 140706668533504] [client 127.0.0.1:59826]     self._setup(name)
[Tue Apr 22 11:58:53.745780 2014] [:error] [pid 15084:tid 140706668533504] [client 127.0.0.1:59826]   File "/usr/local/lib/python3.3/dist-packages/django/conf/__init__.py", line 49, in _setup
[Tue Apr 22 11:58:53.745805 2014] [:error] [pid 15084:tid 140706668533504] [client 127.0.0.1:59826]     self._wrapped = Settings(settings_module)
[Tue Apr 22 11:58:53.745824 2014] [:error] [pid 15084:tid 140706668533504] [client 127.0.0.1:59826]   File "/usr/local/lib/python3.3/dist-packages/django/conf/__init__.py", line 132, in __init__
[Tue Apr 22 11:58:53.745868 2014] [:error] [pid 15084:tid 140706668533504] [client 127.0.0.1:59826]     % (self.SETTINGS_MODULE, e)
[Tue Apr 22 11:58:53.745898 2014] [:error] [pid 15084:tid 140706668533504] [client 127.0.0.1:59826] ImportError: Could not import settings 'ip.settings' (Is it on sys.path? Is there an import error in the settings file?): No module named 'ip'
[Tue Apr 22 11:58:54.458009 2014] [:error] [pid 15084:tid 140706676926208] [client 127.0.0.1:59827] mod_wsgi (pid=15084): Exception occurred processing WSGI script '/var/www/getip.com/ip/wsgi.py'.
[Tue Apr 22 11:58:54.458085 2014] [:error] [pid 15084:tid 140706676926208] [client 127.0.0.1:59827] Traceback (most recent call last):
[Tue Apr 22 11:58:54.458108 2014] [:error] [pid 15084:tid 140706676926208] [client 127.0.0.1:59827]   File "/usr/local/lib/python3.3/dist-packages/django/conf/__init__.py", line 128, in __init__
[Tue Apr 22 11:58:54.458136 2014] [:error] [pid 15084:tid 140706676926208] [client 127.0.0.1:59827]     mod = importlib.import_module(self.SETTINGS_MODULE)
[Tue Apr 22 11:58:54.458147 2014] [:error] [pid 15084:tid 140706676926208] [client 127.0.0.1:59827]   File "/usr/lib/python3.3/importlib/__init__.py", line 90, in import_module
[Tue Apr 22 11:58:54.458165 2014] [:error] [pid 15084:tid 140706676926208] [client 127.0.0.1:59827]     return _bootstrap._gcd_import(name[level:], package, level)
[Tue Apr 22 11:58:54.458174 2014] [:error] [pid 15084:tid 140706676926208] [client 127.0.0.1:59827]   File "<frozen importlib._bootstrap>", line 1584, in _gcd_import
[Tue Apr 22 11:58:54.458188 2014] [:error] [pid 15084:tid 140706676926208] [client 127.0.0.1:59827]   File "<frozen importlib._bootstrap>", line 1565, in _find_and_load
[Tue Apr 22 11:58:54.458200 2014] [:error] [pid 15084:tid 140706676926208] [client 127.0.0.1:59827]   File "<frozen importlib._bootstrap>", line 1512, in _find_and_load_unlocked
[Tue Apr 22 11:58:54.458211 2014] [:error] [pid 15084:tid 140706676926208] [client 127.0.0.1:59827]   File "<frozen importlib._bootstrap>", line 313, in _call_with_frames_removed
[Tue Apr 22 11:58:54.458221 2014] [:error] [pid 15084:tid 140706676926208] [client 127.0.0.1:59827]   File "<frozen importlib._bootstrap>", line 1584, in _gcd_import
[Tue Apr 22 11:58:54.458232 2014] [:error] [pid 15084:tid 140706676926208] [client 127.0.0.1:59827]   File "<frozen importlib._bootstrap>", line 1565, in _find_and_load
[Tue Apr 22 11:58:54.458242 2014] [:error] [pid 15084:tid 140706676926208] [client 127.0.0.1:59827]   File "<frozen importlib._bootstrap>", line 1529, in _find_and_load_unlocked
[Tue Apr 22 11:58:54.458261 2014] [:error] [pid 15084:tid 140706676926208] [client 127.0.0.1:59827] ImportError: No module named 'ip'
[Tue Apr 22 11:58:54.458271 2014] [:error] [pid 15084:tid 140706676926208] [client 127.0.0.1:59827] 
[Tue Apr 22 11:58:54.458275 2014] [:error] [pid 15084:tid 140706676926208] [client 127.0.0.1:59827] During handling of the above exception, another exception occurred:
[Tue Apr 22 11:58:54.458278 2014] [:error] [pid 15084:tid 140706676926208] [client 127.0.0.1:59827] 
[Tue Apr 22 11:58:54.458284 2014] [:error] [pid 15084:tid 140706676926208] [client 127.0.0.1:59827] Traceback (most recent call last):
[Tue Apr 22 11:58:54.458295 2014] [:error] [pid 15084:tid 140706676926208] [client 127.0.0.1:59827]   File "/usr/local/lib/python3.3/dist-packages/django/core/handlers/wsgi.py", line 187, in __call__
[Tue Apr 22 11:58:54.458314 2014] [:error] [pid 15084:tid 140706676926208] [client 127.0.0.1:59827]     self.load_middleware()
[Tue Apr 22 11:58:54.458324 2014] [:error] [pid 15084:tid 140706676926208] [client 127.0.0.1:59827]   File "/usr/local/lib/python3.3/dist-packages/django/core/handlers/base.py", line 46, in load_middleware
[Tue Apr 22 11:58:54.458340 2014] [:error] [pid 15084:tid 140706676926208] [client 127.0.0.1:59827]     for middleware_path in settings.MIDDLEWARE_CLASSES:
[Tue Apr 22 11:58:54.458349 2014] [:error] [pid 15084:tid 140706676926208] [client 127.0.0.1:59827]   File "/usr/local/lib/python3.3/dist-packages/django/conf/__init__.py", line 54, in __getattr__
[Tue Apr 22 11:58:54.458377 2014] [:error] [pid 15084:tid 140706676926208] [client 127.0.0.1:59827]     self._setup(name)
[Tue Apr 22 11:58:54.458387 2014] [:error] [pid 15084:tid 140706676926208] [client 127.0.0.1:59827]   File "/usr/local/lib/python3.3/dist-packages/django/conf/__init__.py", line 49, in _setup
[Tue Apr 22 11:58:54.458402 2014] [:error] [pid 15084:tid 140706676926208] [client 127.0.0.1:59827]     self._wrapped = Settings(settings_module)
[Tue Apr 22 11:58:54.458411 2014] [:error] [pid 15084:tid 140706676926208] [client 127.0.0.1:59827]   File "/usr/local/lib/python3.3/dist-packages/django/conf/__init__.py", line 132, in __init__
[Tue Apr 22 11:58:54.458426 2014] [:error] [pid 15084:tid 140706676926208] [client 127.0.0.1:59827]     % (self.SETTINGS_MODULE, e)
[Tue Apr 22 11:58:54.458439 2014] [:error] [pid 15084:tid 140706676926208] [client 127.0.0.1:59827] ImportError: Could not import settings 'ip.settings' (Is it on sys.path? Is there an import error in the settings file?): No module named 'ip'
[Tue Apr 22 12:00:35.913769 2014] [:error] [pid 15260:tid 140551101794048] [client 127.0.0.1:59828] mod_wsgi (pid=15260): Exception occurred processing WSGI script '/var/www/getip.com/ip/wsgi.py'.
[Tue Apr 22 12:00:35.913904 2014] [:error] [pid 15260:tid 140551101794048] [client 127.0.0.1:59828] Traceback (most recent call last):
[Tue Apr 22 12:00:35.913950 2014] [:error] [pid 15260:tid 140551101794048] [client 127.0.0.1:59828]   File "/usr/local/lib/python3.3/dist-packages/django/conf/__init__.py", line 128, in __init__
[Tue Apr 22 12:00:35.914118 2014] [:error] [pid 15260:tid 140551101794048] [client 127.0.0.1:59828]     mod = importlib.import_module(self.SETTINGS_MODULE)
[Tue Apr 22 12:00:35.914157 2014] [:error] [pid 15260:tid 140551101794048] [client 127.0.0.1:59828]   File "/usr/lib/python3.3/importlib/__init__.py", line 90, in import_module
[Tue Apr 22 12:00:35.914263 2014] [:error] [pid 15260:tid 140551101794048] [client 127.0.0.1:59828]     return _bootstrap._gcd_import(name[level:], package, level)
[Tue Apr 22 12:00:35.914300 2014] [:error] [pid 15260:tid 140551101794048] [client 127.0.0.1:59828]   File "<frozen importlib._bootstrap>", line 1584, in _gcd_import
[Tue Apr 22 12:00:35.914336 2014] [:error] [pid 15260:tid 140551101794048] [client 127.0.0.1:59828]   File "<frozen importlib._bootstrap>", line 1565, in _find_and_load
[Tue Apr 22 12:00:35.914373 2014] [:error] [pid 15260:tid 140551101794048] [client 127.0.0.1:59828]   File "<frozen importlib._bootstrap>", line 1512, in _find_and_load_unlocked
[Tue Apr 22 12:00:35.914407 2014] [:error] [pid 15260:tid 140551101794048] [client 127.0.0.1:59828]   File "<frozen importlib._bootstrap>", line 313, in _call_with_frames_removed
[Tue Apr 22 12:00:35.914441 2014] [:error] [pid 15260:tid 140551101794048] [client 127.0.0.1:59828]   File "<frozen importlib._bootstrap>", line 1584, in _gcd_import
[Tue Apr 22 12:00:35.914475 2014] [:error] [pid 15260:tid 140551101794048] [client 127.0.0.1:59828]   File "<frozen importlib._bootstrap>", line 1565, in _find_and_load
[Tue Apr 22 12:00:35.914509 2014] [:error] [pid 15260:tid 140551101794048] [client 127.0.0.1:59828]   File "<frozen importlib._bootstrap>", line 1529, in _find_and_load_unlocked
[Tue Apr 22 12:00:35.914551 2014] [:error] [pid 15260:tid 140551101794048] [client 127.0.0.1:59828] ImportError: No module named 'ip'
[Tue Apr 22 12:00:35.914583 2014] [:error] [pid 15260:tid 140551101794048] [client 127.0.0.1:59828] 
[Tue Apr 22 12:00:35.914605 2014] [:error] [pid 15260:tid 140551101794048] [client 127.0.0.1:59828] During handling of the above exception, another exception occurred:
[Tue Apr 22 12:00:35.914624 2014] [:error] [pid 15260:tid 140551101794048] [client 127.0.0.1:59828] 
[Tue Apr 22 12:00:35.914651 2014] [:error] [pid 15260:tid 140551101794048] [client 127.0.0.1:59828] Traceback (most recent call last):
[Tue Apr 22 12:00:35.914685 2014] [:error] [pid 15260:tid 140551101794048] [client 127.0.0.1:59828]   File "/usr/local/lib/python3.3/dist-packages/django/core/handlers/wsgi.py", line 187, in __call__
[Tue Apr 22 12:00:35.914849 2014] [:error] [pid 15260:tid 140551101794048] [client 127.0.0.1:59828]     self.load_middleware()
[Tue Apr 22 12:00:35.914887 2014] [:error] [pid 15260:tid 140551101794048] [client 127.0.0.1:59828]   File "/usr/local/lib/python3.3/dist-packages/django/core/handlers/base.py", line 46, in load_middleware
[Tue Apr 22 12:00:35.915037 2014] [:error] [pid 15260:tid 140551101794048] [client 127.0.0.1:59828]     for middleware_path in settings.MIDDLEWARE_CLASSES:
[Tue Apr 22 12:00:35.915074 2014] [:error] [pid 15260:tid 140551101794048] [client 127.0.0.1:59828]   File "/usr/local/lib/python3.3/dist-packages/django/conf/__init__.py", line 54, in __getattr__
[Tue Apr 22 12:00:35.915117 2014] [:error] [pid 15260:tid 140551101794048] [client 127.0.0.1:59828]     self._setup(name)
[Tue Apr 22 12:00:35.915148 2014] [:error] [pid 15260:tid 140551101794048] [client 127.0.0.1:59828]   File "/usr/local/lib/python3.3/dist-packages/django/conf/__init__.py", line 49, in _setup
[Tue Apr 22 12:00:35.915189 2014] [:error] [pid 15260:tid 140551101794048] [client 127.0.0.1:59828]     self._wrapped = Settings(settings_module)
[Tue Apr 22 12:00:35.915222 2014] [:error] [pid 15260:tid 140551101794048] [client 127.0.0.1:59828]   File "/usr/local/lib/python3.3/dist-packages/django/conf/__init__.py", line 132, in __init__
[Tue Apr 22 12:00:35.915260 2014] [:error] [pid 15260:tid 140551101794048] [client 127.0.0.1:59828]     % (self.SETTINGS_MODULE, e)
[Tue Apr 22 12:00:35.915294 2014] [:error] [pid 15260:tid 140551101794048] [client 127.0.0.1:59828] ImportError: Could not import settings 'ip.settings' (Is it on sys.path? Is there an import error in the settings file?): No module named 'ip'
